Workbook
Name BabyCoilIDList: 'Coil to Slit'!$D$3:$D$500
Name BundleIDList: OFFSET('Bundle Formation'!$G$3,0,0,MAX(COUNTIF('Bundle Formation'!$G$3:$G$117,"BND-*"),1),1)
Name CoilIDList: 'Coil Sheet at Plant'!$C$3:$C$100
Name Density_T_mm3: SOP!$B$8
Name MaterialInfoList: 'SKU Master'!$C$2:$C$233
Name SKU_1: "Helpers!$K$2:$K$20"
Name SKU_2: "Helpers!$L$2:$L$9"
Name SKU_3: "Helpers!$M$2:$M$9"
Name SKU_4: "Helpers!$N$2:$N$7"
Name SKU_5: "Helpers!$O$2:$O$11"
Name SKU_6: "Helpers!$P$2:$P$5"

Sheet Coil Sheet at Plant
A1: 🔵 Input Parameters | C1: 🟢 Auto-ID | N1: 🟢 Performance Metrics | Q1: 🔵 Chemistry (Input) | U1: 🟡 Validation Helpers
A2: Date of Inward | B2: HR Coil No. | C2: HR Coil ID | D2: Input Coil Number (Batch ID) | E2: Coil Grade | F2: Heat Number | G2: Thickness (mm) | H2: Length (mm) | I2: Width (mm) | J2: Invoice Weight (T) | K2: Actual Weight (T) | L2: Cost Price (₹) | M2: PO Number | N2: FG Readiness | O2: Dispatched Weight (T) | P2: Yield % (Dispatch/Total Weight) | Q2: Carbon | R2: Mn | S2: YS (MPa) | T2: Elongation (%) | U2: Total Baby Coil Width (mm) | V2: Width Check (Baby vs Parent) | W2: Duplicate ID Check
A3: 46108 | B3: 1 | C3: =IF(OR(A3="",B3=""),"","HYD-"&TEXT(A3,"MMYY")&"-"&TEXT(B3,"00")) -> HYD-0326-01 | D3: C102781102 | E3: E250- BR | F3: C102781 | G3: 2.8 | I3: 1250 | J3: 20.63 | U3: =IF(C3="","",SUMIF('Coil to Slit'!B:B,C3,'Coil to Slit'!G:G)) -> 1243 | V3: =IF(U3="","",IF(I3="","⚠ NO PARENT WIDTH",IF(U3>I3,"⚠ EXCEEDS PARENT","✔ OK"))) -> ✔ OK | W3: =IF(C3="","",IF(COUNTIF(C$3:C3,C3)>1,"⚠ DUPLICATE ID",""))
A4: 46108 | B4: 2 | C4: =IF(OR(A4="",B4=""),"","HYD-"&TEXT(A4,"MMYY")&"-"&TEXT(B4,"00")) -> HYD-0326-02 | D4: C202753205 | E4: E250- BR | F4: C202753 | G4: 2.8 | I4: 1250 | J4: 20.93 | U4: =IF(C4="","",SUMIF('Coil to Slit'!B:B,C4,'Coil to Slit'!G:G)) -> 1243 | V4: =IF(U4="","",IF(I4="","⚠ NO PARENT WIDTH",IF(U4>I4,"⚠ EXCEEDS PARENT","✔ OK"))) -> ✔ OK | W4: =IF(C4="","",IF(COUNTIF(C$3:C4,C4)>1,"⚠ DUPLICATE ID",""))
A5: 46109 | B5: 3 | C5: =IF(OR(A5="",B5=""),"","HYD-"&TEXT(A5,"MMYY")&"-"&TEXT(B5,"00")) -> HYD-0326-03 | D5: K633360481 | E5: IS10748 Gr 1 | F5: A3Y2286 | G5: 2.5 | I5: 1500 | J5: 29.29 | U5: =IF(C5="","",SUMIF('Coil to Slit'!B:B,C5,'Coil to Slit'!G:G)) -> 1504 | V5: =IF(U5="","",IF(I5="","⚠ NO PARENT WIDTH",IF(U5>I5,"⚠ EXCEEDS PARENT","✔ OK"))) -> ⚠ EXCEEDS PARENT | W5: =IF(C5="","",IF(COUNTIF(C$3:C5,C5)>1,"⚠ DUPLICATE ID",""))
A6: 46110 | B6: 4 | C6: =IF(OR(A6="",B6=""),"","HYD-"&TEXT(A6,"MMYY")&"-"&TEXT(B6,"00")) -> HYD-0326-04 | D6: 257334077 | E6: IS10748 Gr 2 | F6: 25A3330 | G6: 2.2 | I6: 1250 | J6: 28.46 | U6: =IF(C6="","",SUMIF('Coil to Slit'!B:B,C6,'Coil to Slit'!G:G)) -> 1251 | V6: =IF(U6="","",IF(I6="","⚠ NO PARENT WIDTH",IF(U6>I6,"⚠ EXCEEDS PARENT","✔ OK"))) -> ⚠ EXCEEDS PARENT | W6: =IF(C6="","",IF(COUNTIF(C$3:C6,C6)>1,"⚠ DUPLICATE ID",""))
A7: 46115 | B7: 5 | C7: =IF(OR(A7="",B7=""),"","HYD-"&TEXT(A7,"MMYY")&"-"&TEXT(B7,"00")) -> HYD-0426-05 | D7: 26210917 | E7: HR2 | F7: H111261 | G7: 2 | I7: 1260 | J7: 19.815 | K7: 19.815 | L7: 11,65,122.0 | M7: JOO-0BGCK1QR7 | U7: =IF(C7="","",SUMIF('Coil to Slit'!B:B,C7,'Coil to Slit'!G:G)) -> 1259 | V7: =IF(U7="","",IF(I7="","⚠ NO PARENT WIDTH",IF(U7>I7,"⚠ EXCEEDS PARENT","✔ OK"))) -> ✔ OK | W7: =IF(C7="","",IF(COUNTIF(C$3:C7,C7)>1,"⚠ DUPLICATE ID",""))
A8: 46115 | B8: 6 | C8: =IF(OR(A8="",B8=""),"","HYD-"&TEXT(A8,"MMYY")&"-"&TEXT(B8,"00")) -> HYD-0426-06 | D8: 26242114 | E8: HR2 | F8: H113559 | G8: 2 | I8: 1264 | J8: 22.13 | K8: 22.13 | L8: 13,01,244.0 | M8: JOO-0BGCK1QR7 | U8: =IF(C8="","",SUMIF('Coil to Slit'!B:B,C8,'Coil to Slit'!G:G)) -> 1259 | V8: =IF(U8="","",IF(I8="","⚠ NO PARENT WIDTH",IF(U8>I8,"⚠ EXCEEDS PARENT","✔ OK"))) -> ✔ OK | W8: =IF(C8="","",IF(COUNTIF(C$3:C8,C8)>1,"⚠ DUPLICATE ID",""))
A9: 46115 | B9: 7 | C9: =IF(OR(A9="",B9=""),"","HYD-"&TEXT(A9,"MMYY")&"-"&TEXT(B9,"00")) -> HYD-0426-07 | D9: 26004175 | E9: HR2 | F9: B589219 | G9: 2 | I9: 930 | J9: 14.08 | K9: 14.08 | L9: 8,37,760.00 | M9: JOO-0BGCK1QR7 | U9: =IF(C9="","",SUMIF('Coil to Slit'!B:B,C9,'Coil to Slit'!G:G)) -> 922 | V9: =IF(U9="","",IF(I9="","⚠ NO PARENT WIDTH",IF(U9>I9,"⚠ EXCEEDS PARENT","✔ OK"))) -> ✔ OK | W9: =IF(C9="","",IF(COUNTIF(C$3:C9,C9)>1,"⚠ DUPLICATE ID",""))
C10: =IF(OR(A10="",B10=""),"","HYD-"&TEXT(A10,"MMYY")&"-"&TEXT(B10,"00")) | U10: =IF(C10="","",SUMIF('Coil to Slit'!B:B,C10,'Coil to Slit'!G:G)) | V10: =IF(U10="","",IF(I10="","⚠ NO PARENT WIDTH",IF(U10>I10,"⚠ EXCEEDS PARENT","✔ OK"))) | W10: =IF(C10="","",IF(COUNTIF(C$3:C10,C10)>1,"⚠ DUPLICATE ID",""))
C11: =IF(OR(A11="",B11=""),"","HYD-"&TEXT(A11,"MMYY")&"-"&TEXT(B11,"00")) | U11: =IF(C11="","",SUMIF('Coil to Slit'!B:B,C11,'Coil to Slit'!G:G)) | V11: =IF(U11="","",IF(I11="","⚠ NO PARENT WIDTH",IF(U11>I11,"⚠ EXCEEDS PARENT","✔ OK"))) | W11: =IF(C11="","",IF(COUNTIF(C$3:C11,C11)>1,"⚠ DUPLICATE ID",""))
C12: =IF(OR(A12="",B12=""),"","HYD-"&TEXT(A12,"MMYY")&"-"&TEXT(B12,"00")) | U12: =IF(C12="","",SUMIF('Coil to Slit'!B:B,C12,'Coil to Slit'!G:G)) | V12: =IF(U12="","",IF(I12="","⚠ NO PARENT WIDTH",IF(U12>I12,"⚠ EXCEEDS PARENT","✔ OK"))) | W12: =IF(C12="","",IF(COUNTIF(C$3:C12,C12)>1,"⚠ DUPLICATE ID",""))
C13: =IF(OR(A13="",B13=""),"","HYD-"&TEXT(A13,"MMYY")&"-"&TEXT(B13,"00")) | U13: =IF(C13="","",SUMIF('Coil to Slit'!B:B,C13,'Coil to Slit'!G:G)) | V13: =IF(U13="","",IF(I13="","⚠ NO PARENT WIDTH",IF(U13>I13,"⚠ EXCEEDS PARENT","✔ OK"))) | W13: =IF(C13="","",IF(COUNTIF(C$3:C13,C13)>1,"⚠ DUPLICATE ID",""))
C14: =IF(OR(A14="",B14=""),"","HYD-"&TEXT(A14,"MMYY")&"-"&TEXT(B14,"00")) | U14: =IF(C14="","",SUMIF('Coil to Slit'!B:B,C14,'Coil to Slit'!G:G)) | V14: =IF(U14="","",IF(I14="","⚠ NO PARENT WIDTH",IF(U14>I14,"⚠ EXCEEDS PARENT","✔ OK"))) | W14: =IF(C14="","",IF(COUNTIF(C$3:C14,C14)>1,"⚠ DUPLICATE ID",""))
C15: =IF(OR(A15="",B15=""),"","HYD-"&TEXT(A15,"MMYY")&"-"&TEXT(B15,"00")) | U15: =IF(C15="","",SUMIF('Coil to Slit'!B:B,C15,'Coil to Slit'!G:G)) | V15: =IF(U15="","",IF(I15="","⚠ NO PARENT WIDTH",IF(U15>I15,"⚠ EXCEEDS PARENT","✔ OK"))) | W15: =IF(C15="","",IF(COUNTIF(C$3:C15,C15)>1,"⚠ DUPLICATE ID",""))
C16: =IF(OR(A16="",B16=""),"","HYD-"&TEXT(A16,"MMYY")&"-"&TEXT(B16,"00")) | U16: =IF(C16="","",SUMIF('Coil to Slit'!B:B,C16,'Coil to Slit'!G:G)) | V16: =IF(U16="","",IF(I16="","⚠ NO PARENT WIDTH",IF(U16>I16,"⚠ EXCEEDS PARENT","✔ OK"))) | W16: =IF(C16="","",IF(COUNTIF(C$3:C16,C16)>1,"⚠ DUPLICATE ID",""))
C17: =IF(OR(A17="",B17=""),"","HYD-"&TEXT(A17,"MMYY")&"-"&TEXT(B17,"00")) | U17: =IF(C17="","",SUMIF('Coil to Slit'!B:B,C17,'Coil to Slit'!G:G)) | V17: =IF(U17="","",IF(I17="","⚠ NO PARENT WIDTH",IF(U17>I17,"⚠ EXCEEDS PARENT","✔ OK"))) | W17: =IF(C17="","",IF(COUNTIF(C$3:C17,C17)>1,"⚠ DUPLICATE ID",""))
C18: =IF(OR(A18="",B18=""),"","HYD-"&TEXT(A18,"MMYY")&"-"&TEXT(B18,"00")) | U18: =IF(C18="","",SUMIF('Coil to Slit'!B:B,C18,'Coil to Slit'!G:G)) | V18: =IF(U18="","",IF(I18="","⚠ NO PARENT WIDTH",IF(U18>I18,"⚠ EXCEEDS PARENT","✔ OK"))) | W18: =IF(C18="","",IF(COUNTIF(C$3:C18,C18)>1,"⚠ DUPLICATE ID",""))
C19: =IF(OR(A19="",B19=""),"","HYD-"&TEXT(A19,"MMYY")&"-"&TEXT(B19,"00")) | U19: =IF(C19="","",SUMIF('Coil to Slit'!B:B,C19,'Coil to Slit'!G:G)) | V19: =IF(U19="","",IF(I19="","⚠ NO PARENT WIDTH",IF(U19>I19,"⚠ EXCEEDS PARENT","✔ OK"))) | W19: =IF(C19="","",IF(COUNTIF(C$3:C19,C19)>1,"⚠ DUPLICATE ID",""))
C20: =IF(OR(A20="",B20=""),"","HYD-"&TEXT(A20,"MMYY")&"-"&TEXT(B20,"00")) | U20: =IF(C20="","",SUMIF('Coil to Slit'!B:B,C20,'Coil to Slit'!G:G)) | V20: =IF(U20="","",IF(I20="","⚠ NO PARENT WIDTH",IF(U20>I20,"⚠ EXCEEDS PARENT","✔ OK"))) | W20: =IF(C20="","",IF(COUNTIF(C$3:C20,C20)>1,"⚠ DUPLICATE ID",""))
C21: =IF(OR(A21="",B21=""),"","HYD-"&TEXT(A21,"MMYY")&"-"&TEXT(B21,"00")) | U21: =IF(C21="","",SUMIF('Coil to Slit'!B:B,C21,'Coil to Slit'!G:G)) | V21: =IF(U21="","",IF(I21="","⚠ NO PARENT WIDTH",IF(U21>I21,"⚠ EXCEEDS PARENT","✔ OK"))) | W21: =IF(C21="","",IF(COUNTIF(C$3:C21,C21)>1,"⚠ DUPLICATE ID",""))
... C100: =IF(OR(A100="",B100=""),"","HYD-"&TEXT(A100,"MMYY")&"-"&TEXT(B100,"00")) | U100: =IF(C100="","",SUMIF('Coil to Slit'!B:B,C100,'Coil to Slit'!G:G)) | V100: =IF(U100="","",IF(I100="","⚠ NO PARENT WIDTH",IF(U100>I100,"⚠ EXCEEDS PARENT","✔ OK"))) | W100: =IF(C100="","",IF(COUNTIF(C$3:C100,C100)>1,"⚠ DUPLICATE ID",""))

Sheet Coil to Slit
A1: 🔵 Manual Entry ↓ | K1: 🟡 Validation Helpers ↓
A2: Date of Conversion | B2: HR Coil ID | C2: Baby Coil Entry (A,B,C...) | D2: Baby Coil ID | E2: Thickness (mm) | F2: Length (mm) | G2: Width (mm) | H2: Weight (T) | I2: Cost Price (₹) | J2: PO Number | K2: Sum Baby Width for HR Coil (mm) | L2: Parent Coil Width (mm) | M2: Width Validation | N2: Duplicate Baby ID Check | O2: Width Sum vs Parent (mm)
A3: 46108 | B3: HYD-0326-01 | C3: A | D3: =IF(OR(B3="",C3=""),"",CONCATENATE(B3,"-",C3)) -> HYD-0326-01-A | E3: =IF(B3="","",IFERROR(VLOOKUP(B3,'Coil Sheet at Plant'!$C:$G,5,FALSE),"ID Not Found")) -> 2.8 | F3: =IF(B3="","",IFERROR(VLOOKUP(B3,'Coil Sheet at Plant'!$C:$H,6,FALSE),"ID Not Found")) -> 0 | G3: 147 | H3: =IF(OR(B3="",G3=""),"",IFERROR(VLOOKUP(B3,'Coil Sheet at Plant'!$C:$J,8,FALSE),0)*G3/SUMIF(B:B,B3,G:G)) -> 2.4397506 | I3: =IF(B3="","",IFERROR(VLOOKUP(B3,'Coil Sheet at Plant'!$C:$L,9,FALSE),"")) -> 0 | J3: =IF(B3="","",IFERROR(VLOOKUP(B3,'Coil Sheet at Plant'!$C:$M,10,FALSE),"")) -> 0 | K3: =IF(B3="","",SUMIF(B:B,B3,G:G)) -> 1243 | L3: =IF(B3="","",IFERROR(VLOOKUP(B3,'Coil Sheet at Plant'!$C:$I,7,FALSE),"")) -> 1250 | M3: =IF(OR(K3="",L3=""),"",IF(L3=0,"⚠ NO PARENT WIDTH",IF(K3>L3,"⚠ BABY > PARENT","✔ OK"))) -> ✔ OK | N3: =IF(D3="","",IF(COUNTIF(D$3:D3,D3)>1,"⚠ DUPLICATE","")) | O3: =IF(B3="","",SUMIF(B:B,B3,G:G)&" / "&IFERROR(VLOOKUP(B3,'Coil Sheet at Plant'!$C:$I,7,FALSE),"?")&" mm") -> 1243 / 1250 mm
A4: 46108 | B4: HYD-0326-01 | C4: B | D4: =IF(OR(B4="",C4=""),"",CONCATENATE(B4,"-",C4)) -> HYD-0326-01-B | E4: =IF(B4="","",IFERROR(VLOOKUP(B4,'Coil Sheet at Plant'!$C:$G,5,FALSE),"ID Not Found")) -> 2.8 | F4: =IF(B4="","",IFERROR(VLOOKUP(B4,'Coil Sheet at Plant'!$C:$H,6,FALSE),"ID Not Found")) -> 0 | G4: 147 | H4: =IF(OR(B4="",G4=""),"",IFERROR(VLOOKUP(B4,'Coil Sheet at Plant'!$C:$J,8,FALSE),0)*G4/SUMIF(B:B,B4,G:G)) -> 2.4397506 | I4: =IF(B4="","",IFERROR(VLOOKUP(B4,'Coil Sheet at Plant'!$C:$L,9,FALSE),"")) -> 0 | J4: =IF(B4="","",IFERROR(VLOOKUP(B4,'Coil Sheet at Plant'!$C:$M,10,FALSE),"")) -> 0 | K4: =IF(B4="","",SUMIF(B:B,B4,G:G)) -> 1243 | L4: =IF(B4="","",IFERROR(VLOOKUP(B4,'Coil Sheet at Plant'!$C:$I,7,FALSE),"")) -> 1250 | M4: =IF(OR(K4="",L4=""),"",IF(L4=0,"⚠ NO PARENT WIDTH",IF(K4>L4,"⚠ BABY > PARENT","✔ OK"))) -> ✔ OK | N4: =IF(D4="","",IF(COUNTIF(D$3:D4,D4)>1,"⚠ DUPLICATE","")) | O4: =IF(B4="","",SUMIF(B:B,B4,G:G)&" / "&IFERROR(VLOOKUP(B4,'Coil Sheet at Plant'!$C:$I,7,FALSE),"?")&" mm") -> 1243 / 1250 mm
A5: 46108 | B5: HYD-0326-01 | C5: C | D5: =IF(OR(B5="",C5=""),"",CONCATENATE(B5,"-",C5)) -> HYD-0326-01-C | E5: =IF(B5="","",IFERROR(VLOOKUP(B5,'Coil Sheet at Plant'!$C:$G,5,FALSE),"ID Not Found")) -> 2.8 | F5: =IF(B5="","",IFERROR(VLOOKUP(B5,'Coil Sheet at Plant'!$C:$H,6,FALSE),"ID Not Found")) -> 0 | G5: 147 | H5: =IF(OR(B5="",G5=""),"",IFERROR(VLOOKUP(B5,'Coil Sheet at Plant'!$C:$J,8,FALSE),0)*G5/SUMIF(B:B,B5,G:G)) -> 2.4397506 | I5: =IF(B5="","",IFERROR(VLOOKUP(B5,'Coil Sheet at Plant'!$C:$L,9,FALSE),"")) -> 0 | J5: =IF(B5="","",IFERROR(VLOOKUP(B5,'Coil Sheet at Plant'!$C:$M,10,FALSE),"")) -> 0 | K5: =IF(B5="","",SUMIF(B:B,B5,G:G)) -> 1243 | L5: =IF(B5="","",IFERROR(VLOOKUP(B5,'Coil Sheet at Plant'!$C:$I,7,FALSE),"")) -> 1250 | M5: =IF(OR(K5="",L5=""),"",IF(L5=0,"⚠ NO PARENT WIDTH",IF(K5>L5,"⚠ BABY > PARENT","✔ OK"))) -> ✔ OK | N5: =IF(D5="","",IF(COUNTIF(D$3:D5,D5)>1,"⚠ DUPLICATE","")) | O5: =IF(B5="","",SUMIF(B:B,B5,G:G)&" / "&IFERROR(VLOOKUP(B5,'Coil Sheet at Plant'!$C:$I,7,FALSE),"?")&" mm") -> 1243 / 1250 mm
A6: 46108 | B6: HYD-0326-01 | C6: D | D6: =IF(OR(B6="",C6=""),"",CONCATENATE(B6,"-",C6)) -> HYD-0326-01-D | E6: =IF(B6="","",IFERROR(VLOOKUP(B6,'Coil Sheet at Plant'!$C:$G,5,FALSE),"ID Not Found")) -> 2.8 | F6: =IF(B6="","",IFERROR(VLOOKUP(B6,'Coil Sheet at Plant'!$C:$H,6,FALSE),"ID Not Found")) -> 0 | G6: 147 | H6: =IF(OR(B6="",G6=""),"",IFERROR(VLOOKUP(B6,'Coil Sheet at Plant'!$C:$J,8,FALSE),0)*G6/SUMIF(B:B,B6,G:G)) -> 2.4397506 | I6: =IF(B6="","",IFERROR(VLOOKUP(B6,'Coil Sheet at Plant'!$C:$L,9,FALSE),"")) -> 0 | J6: =IF(B6="","",IFERROR(VLOOKUP(B6,'Coil Sheet at Plant'!$C:$M,10,FALSE),"")) -> 0 | K6: =IF(B6="","",SUMIF(B:B,B6,G:G)) -> 1243 | L6: =IF(B6="","",IFERROR(VLOOKUP(B6,'Coil Sheet at Plant'!$C:$I,7,FALSE),"")) -> 1250 | M6: =IF(OR(K6="",L6=""),"",IF(L6=0,"⚠ NO PARENT WIDTH",IF(K6>L6,"⚠ BABY > PARENT","✔ OK"))) -> ✔ OK | N6: =IF(D6="","",IF(COUNTIF(D$3:D6,D6)>1,"⚠ DUPLICATE","")) | O6: =IF(B6="","",SUMIF(B:B,B6,G:G)&" / "&IFERROR(VLOOKUP(B6,'Coil Sheet at Plant'!$C:$I,7,FALSE),"?")&" mm") -> 1243 / 1250 mm
A7: 46108 | B7: HYD-0326-01 | C7: E | D7: =IF(OR(B7="",C7=""),"",CONCATENATE(B7,"-",C7)) -> HYD-0326-01-E | E7: =IF(B7="","",IFERROR(VLOOKUP(B7,'Coil Sheet at Plant'!$C:$G,5,FALSE),"ID Not Found")) -> 2.8 | F7: =IF(B7="","",IFERROR(VLOOKUP(B7,'Coil Sheet at Plant'!$C:$H,6,FALSE),"ID Not Found")) -> 0 | G7: 147 | H7: =IF(OR(B7="",G7=""),"",IFERROR(VLOOKUP(B7,'Coil Sheet at Plant'!$C:$J,8,FALSE),0)*G7/SUMIF(B:B,B7,G:G)) -> 2.4397506 | I7: =IF(B7="","",IFERROR(VLOOKUP(B7,'Coil Sheet at Plant'!$C:$L,9,FALSE),"")) -> 0 | J7: =IF(B7="","",IFERROR(VLOOKUP(B7,'Coil Sheet at Plant'!$C:$M,10,FALSE),"")) -> 0 | K7: =IF(B7="","",SUMIF(B:B,B7,G:G)) -> 1243 | L7: =IF(B7="","",IFERROR(VLOOKUP(B7,'Coil Sheet at Plant'!$C:$I,7,FALSE),"")) -> 1250 | M7: =IF(OR(K7="",L7=""),"",IF(L7=0,"⚠ NO PARENT WIDTH",IF(K7>L7,"⚠ BABY > PARENT","✔ OK"))) -> ✔ OK | N7: =IF(D7="","",IF(COUNTIF(D$3:D7,D7)>1,"⚠ DUPLICATE","")) | O7: =IF(B7="","",SUMIF(B:B,B7,G:G)&" / "&IFERROR(VLOOKUP(B7,'Coil Sheet at Plant'!$C:$I,7,FALSE),"?")&" mm") -> 1243 / 1250 mm
A8: 46108 | B8: HYD-0326-01 | C8: F | D8: =IF(OR(B8="",C8=""),"",CONCATENATE(B8,"-",C8)) -> HYD-0326-01-F | E8: =IF(B8="","",IFERROR(VLOOKUP(B8,'Coil Sheet at Plant'!$C:$G,5,FALSE),"ID Not Found")) -> 2.8 | F8: =IF(B8="","",IFERROR(VLOOKUP(B8,'Coil Sheet at Plant'!$C:$H,6,FALSE),"ID Not Found")) -> 0 | G8: 196 | H8: =IF(OR(B8="",G8=""),"",IFERROR(VLOOKUP(B8,'Coil Sheet at Plant'!$C:$J,8,FALSE),0)*G8/SUMIF(B:B,B8,G:G)) -> 3.2530008 | I8: =IF(B8="","",IFERROR(VLOOKUP(B8,'Coil Sheet at Plant'!$C:$L,9,FALSE),"")) -> 0 | J8: =IF(B8="","",IFERROR(VLOOKUP(B8,'Coil Sheet at Plant'!$C:$M,10,FALSE),"")) -> 0 | K8: =IF(B8="","",SUMIF(B:B,B8,G:G)) -> 1243 | L8: =IF(B8="","",IFERROR(VLOOKUP(B8,'Coil Sheet at Plant'!$C:$I,7,FALSE),"")) -> 1250 | M8: =IF(OR(K8="",L8=""),"",IF(L8=0,"⚠ NO PARENT WIDTH",IF(K8>L8,"⚠ BABY > PARENT","✔ OK"))) -> ✔ OK | N8: =IF(D8="","",IF(COUNTIF(D$3:D8,D8)>1,"⚠ DUPLICATE","")) | O8: =IF(B8="","",SUMIF(B:B,B8,G:G)&" / "&IFERROR(VLOOKUP(B8,'Coil Sheet at Plant'!$C:$I,7,FALSE),"?")&" mm") -> 1243 / 1250 mm
A9: 46108 | B9: HYD-0326-01 | C9: G | D9: =IF(OR(B9="",C9=""),"",CONCATENATE(B9,"-",C9)) -> HYD-0326-01-G | E9: =IF(B9="","",IFERROR(VLOOKUP(B9,'Coil Sheet at Plant'!$C:$G,5,FALSE),"ID Not Found")) -> 2.8 | F9: =IF(B9="","",IFERROR(VLOOKUP(B9,'Coil Sheet at Plant'!$C:$H,6,FALSE),"ID Not Found")) -> 0 | G9: 196 | H9: =IF(OR(B9="",G9=""),"",IFERROR(VLOOKUP(B9,'Coil Sheet at Plant'!$C:$J,8,FALSE),0)*G9/SUMIF(B:B,B9,G:G)) -> 3.2530008 | I9: =IF(B9="","",IFERROR(VLOOKUP(B9,'Coil Sheet at Plant'!$C:$L,9,FALSE),"")) -> 0 | J9: =IF(B9="","",IFERROR(VLOOKUP(B9,'Coil Sheet at Plant'!$C:$M,10,FALSE),"")) -> 0 | K9: =IF(B9="","",SUMIF(B:B,B9,G:G)) -> 1243 | L9: =IF(B9="","",IFERROR(VLOOKUP(B9,'Coil Sheet at Plant'!$C:$I,7,FALSE),"")) -> 1250 | M9: =IF(OR(K9="",L9=""),"",IF(L9=0,"⚠ NO PARENT WIDTH",IF(K9>L9,"⚠ BABY > PARENT","✔ OK"))) -> ✔ OK | N9: =IF(D9="","",IF(COUNTIF(D$3:D9,D9)>1,"⚠ DUPLICATE","")) | O9: =IF(B9="","",SUMIF(B:B,B9,G:G)&" / "&IFERROR(VLOOKUP(B9,'Coil Sheet at Plant'!$C:$I,7,FALSE),"?")&" mm") -> 1243 / 1250 mm
A10: 46108 | B10: HYD-0326-01 | C10: H | D10: =IF(OR(B10="",C10=""),"",CONCATENATE(B10,"-",C10)) -> HYD-0326-01-H | E10: =IF(B10="","",IFERROR(VLOOKUP(B10,'Coil Sheet at Plant'!$C:$G,5,FALSE),"ID Not Found")) -> 2.8 | F10: =IF(B10="","",IFERROR(VLOOKUP(B10,'Coil Sheet at Plant'!$C:$H,6,FALSE),"ID Not Found")) -> 0 | G10: 116 | H10: =IF(OR(B10="",G10=""),"",IFERROR(VLOOKUP(B10,'Coil Sheet at Plant'!$C:$J,8,FALSE),0)*G10/SUMIF(B:B,B10,G:G)) -> 1.9252454 | I10: =IF(B10="","",IFERROR(VLOOKUP(B10,'Coil Sheet at Plant'!$C:$L,9,FALSE),"")) -> 0 | J10: =IF(B10="","",IFERROR(VLOOKUP(B10,'Coil Sheet at Plant'!$C:$M,10,FALSE),"")) -> 0 | K10: =IF(B10="","",SUMIF(B:B,B10,G:G)) -> 1243 | L10: =IF(B10="","",IFERROR(VLOOKUP(B10,'Coil Sheet at Plant'!$C:$I,7,FALSE),"")) -> 1250 | M10: =IF(OR(K10="",L10=""),"",IF(L10=0,"⚠ NO PARENT WIDTH",IF(K10>L10,"⚠ BABY > PARENT","✔ OK"))) -> ✔ OK | N10: =IF(D10="","",IF(COUNTIF(D$3:D10,D10)>1,"⚠ DUPLICATE","")) | O10: =IF(B10="","",SUMIF(B:B,B10,G:G)&" / "&IFERROR(VLOOKUP(B10,'Coil Sheet at Plant'!$C:$I,7,FALSE),"?")&" mm") -> 1243 / 1250 mm
A11: 46108 | B11: HYD-0326-02 | C11: A | D11: =IF(OR(B11="",C11=""),"",CONCATENATE(B11,"-",C11)) -> HYD-0326-02-A | E11: =IF(B11="","",IFERROR(VLOOKUP(B11,'Coil Sheet at Plant'!$C:$G,5,FALSE),"ID Not Found")) -> 2.8 | F11: =IF(B11="","",IFERROR(VLOOKUP(B11,'Coil Sheet at Plant'!$C:$H,6,FALSE),"ID Not Found")) -> 0 | G11: 147 | H11: =IF(OR(B11="",G11=""),"",IFERROR(VLOOKUP(B11,'Coil Sheet at Plant'!$C:$J,8,FALSE),0)*G11/SUMIF(B:B,B11,G:G)) -> 2.4752293 | I11: =IF(B11="","",IFERROR(VLOOKUP(B11,'Coil Sheet at Plant'!$C:$L,9,FALSE),"")) -> 0 | J11: =IF(B11="","",IFERROR(VLOOKUP(B11,'Coil Sheet at Plant'!$C:$M,10,FALSE),"")) -> 0 | K11: =IF(B11="","",SUMIF(B:B,B11,G:G)) -> 1243 | L11: =IF(B11="","",IFERROR(VLOOKUP(B11,'Coil Sheet at Plant'!$C:$I,7,FALSE),"")) -> 1250 | M11: =IF(OR(K11="",L11=""),"",IF(L11=0,"⚠ NO PARENT WIDTH",IF(K11>L11,"⚠ BABY > PARENT","✔ OK"))) -> ✔ OK | N11: =IF(D11="","",IF(COUNTIF(D$3:D11,D11)>1,"⚠ DUPLICATE","")) | O11: =IF(B11="","",SUMIF(B:B,B11,G:G)&" / "&IFERROR(VLOOKUP(B11,'Coil Sheet at Plant'!$C:$I,7,FALSE),"?")&" mm") -> 1243 / 1250 mm
A12: 46108 | B12: HYD-0326-02 | C12: B | D12: =IF(OR(B12="",C12=""),"",CONCATENATE(B12,"-",C12)) -> HYD-0326-02-B | E12: =IF(B12="","",IFERROR(VLOOKUP(B12,'Coil Sheet at Plant'!$C:$G,5,FALSE),"ID Not Found")) -> 2.8 | F12: =IF(B12="","",IFERROR(VLOOKUP(B12,'Coil Sheet at Plant'!$C:$H,6,FALSE),"ID Not Found")) -> 0 | G12: 147 | H12: =IF(OR(B12="",G12=""),"",IFERROR(VLOOKUP(B12,'Coil Sheet at Plant'!$C:$J,8,FALSE),0)*G12/SUMIF(B:B,B12,G:G)) -> 2.4752293 | I12: =IF(B12="","",IFERROR(VLOOKUP(B12,'Coil Sheet at Plant'!$C:$L,9,FALSE),"")) -> 0 | J12: =IF(B12="","",IFERROR(VLOOKUP(B12,'Coil Sheet at Plant'!$C:$M,10,FALSE),"")) -> 0 | K12: =IF(B12="","",SUMIF(B:B,B12,G:G)) -> 1243 | L12: =IF(B12="","",IFERROR(VLOOKUP(B12,'Coil Sheet at Plant'!$C:$I,7,FALSE),"")) -> 1250 | M12: =IF(OR(K12="",L12=""),"",IF(L12=0,"⚠ NO PARENT WIDTH",IF(K12>L12,"⚠ BABY > PARENT","✔ OK"))) -> ✔ OK | N12: =IF(D12="","",IF(COUNTIF(D$3:D12,D12)>1,"⚠ DUPLICATE","")) | O12: =IF(B12="","",SUMIF(B:B,B12,G:G)&" / "&IFERROR(VLOOKUP(B12,'Coil Sheet at Plant'!$C:$I,7,FALSE),"?")&" mm") -> 1243 / 1250 mm
A13: 46108 | B13: HYD-0326-02 | C13: C | D13: =IF(OR(B13="",C13=""),"",CONCATENATE(B13,"-",C13)) -> HYD-0326-02-C | E13: =IF(B13="","",IFERROR(VLOOKUP(B13,'Coil Sheet at Plant'!$C:$G,5,FALSE),"ID Not Found")) -> 2.8 | F13: =IF(B13="","",IFERROR(VLOOKUP(B13,'Coil Sheet at Plant'!$C:$H,6,FALSE),"ID Not Found")) -> 0 | G13: 147 | H13: =IF(OR(B13="",G13=""),"",IFERROR(VLOOKUP(B13,'Coil Sheet at Plant'!$C:$J,8,FALSE),0)*G13/SUMIF(B:B,B13,G:G)) -> 2.4752293 | I13: =IF(B13="","",IFERROR(VLOOKUP(B13,'Coil Sheet at Plant'!$C:$L,9,FALSE),"")) -> 0 | J13: =IF(B13="","",IFERROR(VLOOKUP(B13,'Coil Sheet at Plant'!$C:$M,10,FALSE),"")) -> 0 | K13: =IF(B13="","",SUMIF(B:B,B13,G:G)) -> 1243 | L13: =IF(B13="","",IFERROR(VLOOKUP(B13,'Coil Sheet at Plant'!$C:$I,7,FALSE),"")) -> 1250 | M13: =IF(OR(K13="",L13=""),"",IF(L13=0,"⚠ NO PARENT WIDTH",IF(K13>L13,"⚠ BABY > PARENT","✔ OK"))) -> ✔ OK | N13: =IF(D13="","",IF(COUNTIF(D$3:D13,D13)>1,"⚠ DUPLICATE","")) | O13: =IF(B13="","",SUMIF(B:B,B13,G:G)&" / "&IFERROR(VLOOKUP(B13,'Coil Sheet at Plant'!$C:$I,7,FALSE),"?")&" mm") -> 1243 / 1250 mm
A14: 46108 | B14: HYD-0326-02 | C14: D | D14: =IF(OR(B14="",C14=""),"",CONCATENATE(B14,"-",C14)) -> HYD-0326-02-D | E14: =IF(B14="","",IFERROR(VLOOKUP(B14,'Coil Sheet at Plant'!$C:$G,5,FALSE),"ID Not Found")) -> 2.8 | F14: =IF(B14="","",IFERROR(VLOOKUP(B14,'Coil Sheet at Plant'!$C:$H,6,FALSE),"ID Not Found")) -> 0 | G14: 147 | H14: =IF(OR(B14="",G14=""),"",IFERROR(VLOOKUP(B14,'Coil Sheet at Plant'!$C:$J,8,FALSE),0)*G14/SUMIF(B:B,B14,G:G)) -> 2.4752293 | I14: =IF(B14="","",IFERROR(VLOOKUP(B14,'Coil Sheet at Plant'!$C:$L,9,FALSE),"")) -> 0 | J14: =IF(B14="","",IFERROR(VLOOKUP(B14,'Coil Sheet at Plant'!$C:$M,10,FALSE),"")) -> 0 | K14: =IF(B14="","",SUMIF(B:B,B14,G:G)) -> 1243 | L14: =IF(B14="","",IFERROR(VLOOKUP(B14,'Coil Sheet at Plant'!$C:$I,7,FALSE),"")) -> 1250 | M14: =IF(OR(K14="",L14=""),"",IF(L14=0,"⚠ NO PARENT WIDTH",IF(K14>L14,"⚠ BABY > PARENT","✔ OK"))) -> ✔ OK | N14: =IF(D14="","",IF(COUNTIF(D$3:D14,D14)>1,"⚠ DUPLICATE","")) | O14: =IF(B14="","",SUMIF(B:B,B14,G:G)&" / "&IFERROR(VLOOKUP(B14,'Coil Sheet at Plant'!$C:$I,7,FALSE),"?")&" mm") -> 1243 / 1250 mm
... A28: 46109 | B28: HYD-0326-03 | C28: J | D28: =IF(OR(B28="",C28=""),"",CONCATENATE(B28,"-",C28)) -> HYD-0326-03-J | E28: =IF(B28="","",IFERROR(VLOOKUP(B28,'Coil Sheet at Plant'!$C:$G,5,FALSE),"ID Not Found")) -> 2.5 | F28: =IF(B28="","",IFERROR(VLOOKUP(B28,'Coil Sheet at Plant'!$C:$H,6,FALSE),"ID Not Found")) -> 0 | G28: 96 | H28: =IF(OR(B28="",G28=""),"",IFERROR(VLOOKUP(B28,'Coil Sheet at Plant'!$C:$J,8,FALSE),0)*G28/SUMIF(B:B,B28,G:G)) -> 1.8695745 | I28: =IF(B28="","",IFERROR(VLOOKUP(B28,'Coil Sheet at Plant'!$C:$L,9,FALSE),"")) -> 0 | J28: =IF(B28="","",IFERROR(VLOOKUP(B28,'Coil Sheet at Plant'!$C:$M,10,FALSE),"")) -> 0 | K28: =IF(B28="","",SUMIF(B:B,B28,G:G)) -> 1504 | L28: =IF(B28="","",IFERROR(VLOOKUP(B28,'Coil Sheet at Plant'!$C:$I,7,FALSE),"")) -> 1500 | M28: =IF(OR(K28="",L28=""),"",IF(L28=0,"⚠ NO PARENT WIDTH",IF(K28>L28,"⚠ BABY > PARENT","✔ OK"))) -> ⚠ BABY > PARENT | N28: =IF(D28="","",IF(COUNTIF(D$3:D28,D28)>1,"⚠ DUPLICATE","")) | O28: =IF(B28="","",SUMIF(B:B,B28,G:G)&" / "&IFERROR(VLOOKUP(B28,'Coil Sheet at Plant'!$C:$I,7,FALSE),"?")&" mm") -> 1504 / 1500 mm
A29: 29-03-2026 | B29: HYD-0326-04 | C29: A | D29: =IF(OR(B29="",C29=""),"",CONCATENATE(B29,"-",C29)) -> HYD-0326-04-A | E29: =IF(B29="","",IFERROR(VLOOKUP(B29,'Coil Sheet at Plant'!$C:$G,5,FALSE),"ID Not Found")) -> 2.2 | F29: =IF(B29="","",IFERROR(VLOOKUP(B29,'Coil Sheet at Plant'!$C:$H,6,FALSE),"ID Not Found")) -> 0 | G29: 148 | H29: =IF(OR(B29="",G29=""),"",IFERROR(VLOOKUP(B29,'Coil Sheet at Plant'!$C:$J,8,FALSE),0)*G29/SUMIF(B:B,B29,G:G)) -> 3.3669704 | I29: =IF(B29="","",IFERROR(VLOOKUP(B29,'Coil Sheet at Plant'!$C:$L,9,FALSE),"")) -> 0 | J29: =IF(B29="","",IFERROR(VLOOKUP(B29,'Coil Sheet at Plant'!$C:$M,10,FALSE),"")) -> 0 | K29: =IF(B29="","",SUMIF(B:B,B29,G:G)) -> 1251 | L29: =IF(B29="","",IFERROR(VLOOKUP(B29,'Coil Sheet at Plant'!$C:$I,7,FALSE),"")) -> 1250 | M29: =IF(OR(K29="",L29=""),"",IF(L29=0,"⚠ NO PARENT WIDTH",IF(K29>L29,"⚠ BABY > PARENT","✔ OK"))) -> ⚠ BABY > PARENT | N29: =IF(D29="","",IF(COUNTIF(D$3:D29,D29)>1,"⚠ DUPLICATE","")) | O29: =IF(B29="","",SUMIF(B:B,B29,G:G)&" / "&IFERROR(VLOOKUP(B29,'Coil Sheet at Plant'!$C:$I,7,FALSE),"?")&" mm") -> 1251 / 1250 mm
A30: 29-03-2026 | B30: HYD-0326-04 | C30: B | D30: =IF(OR(B30="",C30=""),"",CONCATENATE(B30,"-",C30)) -> HYD-0326-04-B | E30: =IF(B30="","",IFERROR(VLOOKUP(B30,'Coil Sheet at Plant'!$C:$G,5,FALSE),"ID Not Found")) -> 2.2 | F30: =IF(B30="","",IFERROR(VLOOKUP(B30,'Coil Sheet at Plant'!$C:$H,6,FALSE),"ID Not Found")) -> 0 | G30: 148 | H30: =IF(OR(B30="",G30=""),"",IFERROR(VLOOKUP(B30,'Coil Sheet at Plant'!$C:$J,8,FALSE),0)*G30/SUMIF(B:B,B30,G:G)) -> 3.3669704 | I30: =IF(B30="","",IFERROR(VLOOKUP(B30,'Coil Sheet at Plant'!$C:$L,9,FALSE),"")) -> 0 | J30: =IF(B30="","",IFERROR(VLOOKUP(B30,'Coil Sheet at Plant'!$C:$M,10,FALSE),"")) -> 0 | K30: =IF(B30="","",SUMIF(B:B,B30,G:G)) -> 1251 | L30: =IF(B30="","",IFERROR(VLOOKUP(B30,'Coil Sheet at Plant'!$C:$I,7,FALSE),"")) -> 1250 | M30: =IF(OR(K30="",L30=""),"",IF(L30=0,"⚠ NO PARENT WIDTH",IF(K30>L30,"⚠ BABY > PARENT","✔ OK"))) -> ⚠ BABY > PARENT | N30: =IF(D30="","",IF(COUNTIF(D$3:D30,D30)>1,"⚠ DUPLICATE","")) | O30: =IF(B30="","",SUMIF(B:B,B30,G:G)&" / "&IFERROR(VLOOKUP(B30,'Coil Sheet at Plant'!$C:$I,7,FALSE),"?")&" mm") -> 1251 / 1250 mm
A31: 29-03-2026 | B31: HYD-0326-04 | C31: C | D31: =IF(OR(B31="",C31=""),"",CONCATENATE(B31,"-",C31)) -> HYD-0326-04-C | E31: =IF(B31="","",IFERROR(VLOOKUP(B31,'Coil Sheet at Plant'!$C:$G,5,FALSE),"ID Not Found")) -> 2.2 | F31: =IF(B31="","",IFERROR(VLOOKUP(B31,'Coil Sheet at Plant'!$C:$H,6,FALSE),"ID Not Found")) -> 0 | G31: 148 | H31: =IF(OR(B31="",G31=""),"",IFERROR(VLOOKUP(B31,'Coil Sheet at Plant'!$C:$J,8,FALSE),0)*G31/SUMIF(B:B,B31,G:G)) -> 3.3669704 | I31: =IF(B31="","",IFERROR(VLOOKUP(B31,'Coil Sheet at Plant'!$C:$L,9,FALSE),"")) -> 0 | J31: =IF(B31="","",IFERROR(VLOOKUP(B31,'Coil Sheet at Plant'!$C:$M,10,FALSE),"")) -> 0 | K31: =IF(B31="","",SUMIF(B:B,B31,G:G)) -> 1251 | L31: =IF(B31="","",IFERROR(VLOOKUP(B31,'Coil Sheet at Plant'!$C:$I,7,FALSE),"")) -> 1250 | M31: =IF(OR(K31="",L31=""),"",IF(L31=0,"⚠ NO PARENT WIDTH",IF(K31>L31,"⚠ BABY > PARENT","✔ OK"))) -> ⚠ BABY > PARENT | N31: =IF(D31="","",IF(COUNTIF(D$3:D31,D31)>1,"⚠ DUPLICATE","")) | O31: =IF(B31="","",SUMIF(B:B,B31,G:G)&" / "&IFERROR(VLOOKUP(B31,'Coil Sheet at Plant'!$C:$I,7,FALSE),"?")&" mm") -> 1251 / 1250 mm
A32: 29-03-2026 | B32: HYD-0326-04 | C32: D | D32: =IF(OR(B32="",C32=""),"",CONCATENATE(B32,"-",C32)) -> HYD-0326-04-D | E32: =IF(B32="","",IFERROR(VLOOKUP(B32,'Coil Sheet at Plant'!$C:$G,5,FALSE),"ID Not Found")) -> 2.2 | F32: =IF(B32="","",IFERROR(VLOOKUP(B32,'Coil Sheet at Plant'!$C:$H,6,FALSE),"ID Not Found")) -> 0 | G32: 148 | H32: =IF(OR(B32="",G32=""),"",IFERROR(VLOOKUP(B32,'Coil Sheet at Plant'!$C:$J,8,FALSE),0)*G32/SUMIF(B:B,B32,G:G)) -> 3.3669704 | I32: =IF(B32="","",IFERROR(VLOOKUP(B32,'Coil Sheet at Plant'!$C:$L,9,FALSE),"")) -> 0 | J32: =IF(B32="","",IFERROR(VLOOKUP(B32,'Coil Sheet at Plant'!$C:$M,10,FALSE),"")) -> 0 | K32: =IF(B32="","",SUMIF(B:B,B32,G:G)) -> 1251 | L32: =IF(B32="","",IFERROR(VLOOKUP(B32,'Coil Sheet at Plant'!$C:$I,7,FALSE),"")) -> 1250 | M32: =IF(OR(K32="",L32=""),"",IF(L32=0,"⚠ NO PARENT WIDTH",IF(K32>L32,"⚠ BABY > PARENT","✔ OK"))) -> ⚠ BABY > PARENT | N32: =IF(D32="","",IF(COUNTIF(D$3:D32,D32)>1,"⚠ DUPLICATE","")) | O32: =IF(B32="","",SUMIF(B:B,B32,G:G)&" / "&IFERROR(VLOOKUP(B32,'Coil Sheet at Plant'!$C:$I,7,FALSE),"?")&" mm") -> 1251 / 1250 mm
A33: 29-03-2026 | B33: HYD-0326-04 | C33: E | D33: =IF(OR(B33="",C33=""),"",CONCATENATE(B33,"-",C33)) -> HYD-0326-04-E | E33: =IF(B33="","",IFERROR(VLOOKUP(B33,'Coil Sheet at Plant'!$C:$G,5,FALSE),"ID Not Found")) -> 2.2 | F33: =IF(B33="","",IFERROR(VLOOKUP(B33,'Coil Sheet at Plant'!$C:$H,6,FALSE),"ID Not Found")) -> 0 | G33: 148 | H33: =IF(OR(B33="",G33=""),"",IFERROR(VLOOKUP(B33,'Coil Sheet at Plant'!$C:$J,8,FALSE),0)*G33/SUMIF(B:B,B33,G:G)) -> 3.3669704 | I33: =IF(B33="","",IFERROR(VLOOKUP(B33,'Coil Sheet at Plant'!$C:$L,9,FALSE),"")) -> 0 | J33: =IF(B33="","",IFERROR(VLOOKUP(B33,'Coil Sheet at Plant'!$C:$M,10,FALSE),"")) -> 0 | K33: =IF(B33="","",SUMIF(B:B,B33,G:G)) -> 1251 | L33: =IF(B33="","",IFERROR(VLOOKUP(B33,'Coil Sheet at Plant'!$C:$I,7,FALSE),"")) -> 1250 | M33: =IF(OR(K33="",L33=""),"",IF(L33=0,"⚠ NO PARENT WIDTH",IF(K33>L33,"⚠ BABY > PARENT","✔ OK"))) -> ⚠ BABY > PARENT | N33: =IF(D33="","",IF(COUNTIF(D$3:D33,D33)>1,"⚠ DUPLICATE","")) | O33: =IF(B33="","",SUMIF(B:B,B33,G:G)&" / "&IFERROR(VLOOKUP(B33,'Coil Sheet at Plant'!$C:$I,7,FALSE),"?")&" mm") -> 1251 / 1250 mm
A34: 29-03-2026 | B34: HYD-0326-04 | C34: F | D34: =IF(OR(B34="",C34=""),"",CONCATENATE(B34,"-",C34)) -> HYD-0326-04-F | E34: =IF(B34="","",IFERROR(VLOOKUP(B34,'Coil Sheet at Plant'!$C:$G,5,FALSE),"ID Not Found")) -> 2.2 | F34: =IF(B34="","",IFERROR(VLOOKUP(B34,'Coil Sheet at Plant'!$C:$H,6,FALSE),"ID Not Found")) -> 0 | G34: 197 | H34: =IF(OR(B34="",G34=""),"",IFERROR(VLOOKUP(B34,'Coil Sheet at Plant'!$C:$J,8,FALSE),0)*G34/SUMIF(B:B,B34,G:G)) -> 4.4817106 | I34: =IF(B34="","",IFERROR(VLOOKUP(B34,'Coil Sheet at Plant'!$C:$L,9,FALSE),"")) -> 0 | J34: =IF(B34="","",IFERROR(VLOOKUP(B34,'Coil Sheet at Plant'!$C:$M,10,FALSE),"")) -> 0 | K34: =IF(B34="","",SUMIF(B:B,B34,G:G)) -> 1251 | L34: =IF(B34="","",IFERROR(VLOOKUP(B34,'Coil Sheet at Plant'!$C:$I,7,FALSE),"")) -> 1250 | M34: =IF(OR(K34="",L34=""),"",IF(L34=0,"⚠ NO PARENT WIDTH",IF(K34>L34,"⚠ BABY > PARENT","✔ OK"))) -> ⚠ BABY > PARENT | N34: =IF(D34="","",IF(COUNTIF(D$3:D34,D34)>1,"⚠ DUPLICATE","")) | O34: =IF(B34="","",SUMIF(B:B,B34,G:G)&" / "&IFERROR(VLOOKUP(B34,'Coil Sheet at Plant'!$C:$I,7,FALSE),"?")&" mm") -> 1251 / 1250 mm
A35: 29-03-2026 | B35: HYD-0326-04 | C35: G | D35: =IF(OR(B35="",C35=""),"",CONCATENATE(B35,"-",C35)) -> HYD-0326-04-G | E35: =IF(B35="","",IFERROR(VLOOKUP(B35,'Coil Sheet at Plant'!$C:$G,5,FALSE),"ID Not Found")) -> 2.2 | F35: =IF(B35="","",IFERROR(VLOOKUP(B35,'Coil Sheet at Plant'!$C:$H,6,FALSE),"ID Not Found")) -> 0 | G35: 197 | H35: =IF(OR(B35="",G35=""),"",IFERROR(VLOOKUP(B35,'Coil Sheet at Plant'!$C:$J,8,FALSE),0)*G35/SUMIF(B:B,B35,G:G)) -> 4.4817106 | I35: =IF(B35="","",IFERROR(VLOOKUP(B35,'Coil Sheet at Plant'!$C:$L,9,FALSE),"")) -> 0 | J35: =IF(B35="","",IFERROR(VLOOKUP(B35,'Coil Sheet at Plant'!$C:$M,10,FALSE),"")) -> 0 | K35: =IF(B35="","",SUMIF(B:B,B35,G:G)) -> 1251 | L35: =IF(B35="","",IFERROR(VLOOKUP(B35,'Coil Sheet at Plant'!$C:$I,7,FALSE),"")) -> 1250 | M35: =IF(OR(K35="",L35=""),"",IF(L35=0,"⚠ NO PARENT WIDTH",IF(K35>L35,"⚠ BABY > PARENT","✔ OK"))) -> ⚠ BABY > PARENT | N35: =IF(D35="","",IF(COUNTIF(D$3:D35,D35)>1,"⚠ DUPLICATE","")) | O35: =IF(B35="","",SUMIF(B:B,B35,G:G)&" / "&IFERROR(VLOOKUP(B35,'Coil Sheet at Plant'!$C:$I,7,FALSE),"?")&" mm") -> 1251 / 1250 mm
A36: 29-03-2026 | B36: HYD-0326-04 | C36: H | D36: =IF(OR(B36="",C36=""),"",CONCATENATE(B36,"-",C36)) -> HYD-0326-04-H | E36: =IF(B36="","",IFERROR(VLOOKUP(B36,'Coil Sheet at Plant'!$C:$G,5,FALSE),"ID Not Found")) -> 2.2 | F36: =IF(B36="","",IFERROR(VLOOKUP(B36,'Coil Sheet at Plant'!$C:$H,6,FALSE),"ID Not Found")) -> 0 | G36: 117 | H36: =IF(OR(B36="",G36=""),"",IFERROR(VLOOKUP(B36,'Coil Sheet at Plant'!$C:$J,8,FALSE),0)*G36/SUMIF(B:B,B36,G:G)) -> 2.6617266 | I36: =IF(B36="","",IFERROR(VLOOKUP(B36,'Coil Sheet at Plant'!$C:$L,9,FALSE),"")) -> 0 | J36: =IF(B36="","",IFERROR(VLOOKUP(B36,'Coil Sheet at Plant'!$C:$M,10,FALSE),"")) -> 0 | K36: =IF(B36="","",SUMIF(B:B,B36,G:G)) -> 1251 | L36: =IF(B36="","",IFERROR(VLOOKUP(B36,'Coil Sheet at Plant'!$C:$I,7,FALSE),"")) -> 1250 | M36: =IF(OR(K36="",L36=""),"",IF(L36=0,"⚠ NO PARENT WIDTH",IF(K36>L36,"⚠ BABY > PARENT","✔ OK"))) -> ⚠ BABY > PARENT | N36: =IF(D36="","",IF(COUNTIF(D$3:D36,D36)>1,"⚠ DUPLICATE","")) | O36: =IF(B36="","",SUMIF(B:B,B36,G:G)&" / "&IFERROR(VLOOKUP(B36,'Coil Sheet at Plant'!$C:$I,7,FALSE),"?")&" mm") -> 1251 / 1250 mm
A37: 46116 | B37: HYD-0426-05 | C37: A | D37: =IF(OR(B37="",C37=""),"",CONCATENATE(B37,"-",C37)) -> HYD-0426-05-A | E37: =IF(B37="","",IFERROR(VLOOKUP(B37,'Coil Sheet at Plant'!$C:$G,5,FALSE),"ID Not Found")) -> 2 | F37: =IF(B37="","",IFERROR(VLOOKUP(B37,'Coil Sheet at Plant'!$C:$H,6,FALSE),"ID Not Found")) | G37: 197 | H37: =IF(OR(B37="",G37=""),"",IFERROR(VLOOKUP(B37,'Coil Sheet at Plant'!$C:$J,8,FALSE),0)*G37/SUMIF(B:B,B37,G:G)) -> 3.1005203 | I37: =IF(B37="","",IFERROR(VLOOKUP(B37,'Coil Sheet at Plant'!$C:$L,9,FALSE),"")) -> 19.815 | J37: =IF(B37="","",IFERROR(VLOOKUP(B37,'Coil Sheet at Plant'!$C:$M,10,FALSE),"")) -> 11,65,122.0 | K37: =IF(B37="","",SUMIF(B:B,B37,G:G)) -> 1259 | L37: =IF(B37="","",IFERROR(VLOOKUP(B37,'Coil Sheet at Plant'!$C:$I,7,FALSE),"")) -> 1260 | M37: =IF(OR(K37="",L37=""),"",IF(L37=0,"⚠ NO PARENT WIDTH",IF(K37>L37,"⚠ BABY > PARENT","✔ OK"))) -> ✔ OK | N37: =IF(D37="","",IF(COUNTIF(D$3:D37,D37)>1,"⚠ DUPLICATE","")) | O37: =IF(B37="","",SUMIF(B:B,B37,G:G)&" / "&IFERROR(VLOOKUP(B37,'Coil Sheet at Plant'!$C:$I,7,FALSE),"?")&" mm") -> 1259 / 1260 mm
A38: 46116 | B38: HYD-0426-05 | C38: B | D38: =IF(OR(B38="",C38=""),"",CONCATENATE(B38,"-",C38)) -> HYD-0426-05-B | E38: =IF(B38="","",IFERROR(VLOOKUP(B38,'Coil Sheet at Plant'!$C:$G,5,FALSE),"ID Not Found")) -> 2 | F38: =IF(B38="","",IFERROR(VLOOKUP(B38,'Coil Sheet at Plant'!$C:$H,6,FALSE),"ID Not Found")) | G38: 197 | H38: =IF(OR(B38="",G38=""),"",IFERROR(VLOOKUP(B38,'Coil Sheet at Plant'!$C:$J,8,FALSE),0)*G38/SUMIF(B:B,B38,G:G)) -> 3.1005203 | I38: =IF(B38="","",IFERROR(VLOOKUP(B38,'Coil Sheet at Plant'!$C:$L,9,FALSE),"")) -> 19.815 | J38: =IF(B38="","",IFERROR(VLOOKUP(B38,'Coil Sheet at Plant'!$C:$M,10,FALSE),"")) -> 11,65,122.0 | K38: =IF(B38="","",SUMIF(B:B,B38,G:G)) -> 1259 | L38: =IF(B38="","",IFERROR(VLOOKUP(B38,'Coil Sheet at Plant'!$C:$I,7,FALSE),"")) -> 1260 | M38: =IF(OR(K38="",L38=""),"",IF(L38=0,"⚠ NO PARENT WIDTH",IF(K38>L38,"⚠ BABY > PARENT","✔ OK"))) -> ✔ OK | N38: =IF(D38="","",IF(COUNTIF(D$3:D38,D38)>1,"⚠ DUPLICATE","")) | O38: =IF(B38="","",SUMIF(B:B,B38,G:G)&" / "&IFERROR(VLOOKUP(B38,'Coil Sheet at Plant'!$C:$I,7,FALSE),"?")&" mm") -> 1259 / 1260 mm
A39: 46116 | B39: HYD-0426-05 | C39: C | D39: =IF(OR(B39="",C39=""),"",CONCATENATE(B39,"-",C39)) -> HYD-0426-05-C | E39: =IF(B39="","",IFERROR(VLOOKUP(B39,'Coil Sheet at Plant'!$C:$G,5,FALSE),"ID Not Found")) -> 2 | F39: =IF(B39="","",IFERROR(VLOOKUP(B39,'Coil Sheet at Plant'!$C:$H,6,FALSE),"ID Not Found")) | G39: 197 | H39: =IF(OR(B39="",G39=""),"",IFERROR(VLOOKUP(B39,'Coil Sheet at Plant'!$C:$J,8,FALSE),0)*G39/SUMIF(B:B,B39,G:G)) -> 3.1005203 | I39: =IF(B39="","",IFERROR(VLOOKUP(B39,'Coil Sheet at Plant'!$C:$L,9,FALSE),"")) -> 19.815 | J39: =IF(B39="","",IFERROR(VLOOKUP(B39,'Coil Sheet at Plant'!$C:$M,10,FALSE),"")) -> 11,65,122.0 | K39: =IF(B39="","",SUMIF(B:B,B39,G:G)) -> 1259 | L39: =IF(B39="","",IFERROR(VLOOKUP(B39,'Coil Sheet at Plant'!$C:$I,7,FALSE),"")) -> 1260 | M39: =IF(OR(K39="",L39=""),"",IF(L39=0,"⚠ NO PARENT WIDTH",IF(K39>L39,"⚠ BABY > PARENT","✔ OK"))) -> ✔ OK | N39: =IF(D39="","",IF(COUNTIF(D$3:D39,D39)>1,"⚠ DUPLICATE","")) | O39: =IF(B39="","",SUMIF(B:B,B39,G:G)&" / "&IFERROR(VLOOKUP(B39,'Coil Sheet at Plant'!$C:$I,7,FALSE),"?")&" mm") -> 1259 / 1260 mm
A40: 46116 | B40: HYD-0426-05 | C40: D | D40: =IF(OR(B40="",C40=""),"",CONCATENATE(B40,"-",C40)) -> HYD-0426-05-D | E40: =IF(B40="","",IFERROR(VLOOKUP(B40,'Coil Sheet at Plant'!$C:$G,5,FALSE),"ID Not Found")) -> 2 | F40: =IF(B40="","",IFERROR(VLOOKUP(B40,'Coil Sheet at Plant'!$C:$H,6,FALSE),"ID Not Found")) | G40: 197 | H40: =IF(OR(B40="",G40=""),"",IFERROR(VLOOKUP(B40,'Coil Sheet at Plant'!$C:$J,8,FALSE),0)*G40/SUMIF(B:B,B40,G:G)) -> 3.1005203 | I40: =IF(B40="","",IFERROR(VLOOKUP(B40,'Coil Sheet at Plant'!$C:$L,9,FALSE),"")) -> 19.815 | J40: =IF(B40="","",IFERROR(VLOOKUP(B40,'Coil Sheet at Plant'!$C:$M,10,FALSE),"")) -> 11,65,122.0 | K40: =IF(B40="","",SUMIF(B:B,B40,G:G)) -> 1259 | L40: =IF(B40="","",IFERROR(VLOOKUP(B40,'Coil Sheet at Plant'!$C:$I,7,FALSE),"")) -> 1260 | M40: =IF(OR(K40="",L40=""),"",IF(L40=0,"⚠ NO PARENT WIDTH",IF(K40>L40,"⚠ BABY > PARENT","✔ OK"))) -> ✔ OK | N40: =IF(D40="","",IF(COUNTIF(D$3:D40,D40)>1,"⚠ DUPLICATE","")) | O40: =IF(B40="","",SUMIF(B:B,B40,G:G)&" / "&IFERROR(VLOOKUP(B40,'Coil Sheet at Plant'!$C:$I,7,FALSE),"?")&" mm") -> 1259 / 1260 mm
A41: 46116 | B41: HYD-0426-05 | C41: E | D41: =IF(OR(B41="",C41=""),"",CONCATENATE(B41,"-",C41)) -> HYD-0426-05-E | E41: =IF(B41="","",IFERROR(VLOOKUP(B41,'Coil Sheet at Plant'!$C:$G,5,FALSE),"ID Not Found")) -> 2 | F41: =IF(B41="","",IFERROR(VLOOKUP(B41,'Coil Sheet at Plant'!$C:$H,6,FALSE),"ID Not Found")) | G41: 197 | H41: =IF(OR(B41="",G41=""),"",IFERROR(VLOOKUP(B41,'Coil Sheet at Plant'!$C:$J,8,FALSE),0)*G41/SUMIF(B:B,B41,G:G)) -> 3.1005203 | I41: =IF(B41="","",IFERROR(VLOOKUP(B41,'Coil Sheet at Plant'!$C:$L,9,FALSE),"")) -> 19.815 | J41: =IF(B41="","",IFERROR(VLOOKUP(B41,'Coil Sheet at Plant'!$C:$M,10,FALSE),"")) -> 11,65,122.0 | K41: =IF(B41="","",SUMIF(B:B,B41,G:G)) -> 1259 | L41: =IF(B41="","",IFERROR(VLOOKUP(B41,'Coil Sheet at Plant'!$C:$I,7,FALSE),"")) -> 1260 | M41: =IF(OR(K41="",L41=""),"",IF(L41=0,"⚠ NO PARENT WIDTH",IF(K41>L41,"⚠ BABY > PARENT","✔ OK"))) -> ✔ OK | N41: =IF(D41="","",IF(COUNTIF(D$3:D41,D41)>1,"⚠ DUPLICATE","")) | O41: =IF(B41="","",SUMIF(B:B,B41,G:G)&" / "&IFERROR(VLOOKUP(B41,'Coil Sheet at Plant'!$C:$I,7,FALSE),"?")&" mm") -> 1259 / 1260 mm
A42: 46116 | B42: HYD-0426-05 | C42: F | D42: =IF(OR(B42="",C42=""),"",CONCATENATE(B42,"-",C42)) -> HYD-0426-05-F | E42: =IF(B42="","",IFERROR(VLOOKUP(B42,'Coil Sheet at Plant'!$C:$G,5,FALSE),"ID Not Found")) -> 2 | F42: =IF(B42="","",IFERROR(VLOOKUP(B42,'Coil Sheet at Plant'!$C:$H,6,FALSE),"ID Not Found")) | G42: 197 | H42: =IF(OR(B42="",G42=""),"",IFERROR(VLOOKUP(B42,'Coil Sheet at Plant'!$C:$J,8,FALSE),0)*G42/SUMIF(B:B,B42,G:G)) -> 3.1005203 | I42: =IF(B42="","",IFERROR(VLOOKUP(B42,'Coil Sheet at Plant'!$C:$L,9,FALSE),"")) -> 19.815 | J42: =IF(B42="","",IFERROR(VLOOKUP(B42,'Coil Sheet at Plant'!$C:$M,10,FALSE),"")) -> 11,65,122.0 | K42: =IF(B42="","",SUMIF(B:B,B42,G:G)) -> 1259 | L42: =IF(B42="","",IFERROR(VLOOKUP(B42,'Coil Sheet at Plant'!$C:$I,7,FALSE),"")) -> 1260 | M42: =IF(OR(K42="",L42=""),"",IF(L42=0,"⚠ NO PARENT WIDTH",IF(K42>L42,"⚠ BABY > PARENT","✔ OK"))) -> ✔ OK | N42: =IF(D42="","",IF(COUNTIF(D$3:D42,D42)>1,"⚠ DUPLICATE","")) | O42: =IF(B42="","",SUMIF(B:B,B42,G:G)&" / "&IFERROR(VLOOKUP(B42,'Coil Sheet at Plant'!$C:$I,7,FALSE),"?")&" mm") -> 1259 / 1260 mm
A43: 46116 | B43: HYD-0426-05 | C43: G | D43: =IF(OR(B43="",C43=""),"",CONCATENATE(B43,"-",C43)) -> HYD-0426-05-G | E43: =IF(B43="","",IFERROR(VLOOKUP(B43,'Coil Sheet at Plant'!$C:$G,5,FALSE),"ID Not Found")) -> 2 | F43: =IF(B43="","",IFERROR(VLOOKUP(B43,'Coil Sheet at Plant'!$C:$H,6,FALSE),"ID Not Found")) | G43: 77 | H43: =IF(OR(B43="",G43=""),"",IFERROR(VLOOKUP(B43,'Coil Sheet at Plant'!$C:$J,8,FALSE),0)*G43/SUMIF(B:B,B43,G:G)) -> 1.2118785 | I43: =IF(B43="","",IFERROR(VLOOKUP(B43,'Coil Sheet at Plant'!$C:$L,9,FALSE),"")) -> 19.815 | J43: =IF(B43="","",IFERROR(VLOOKUP(B43,'Coil Sheet at Plant'!$C:$M,10,FALSE),"")) -> 11,65,122.0 | K43: =IF(B43="","",SUMIF(B:B,B43,G:G)) -> 1259 | L43: =IF(B43="","",IFERROR(VLOOKUP(B43,'Coil Sheet at Plant'!$C:$I,7,FALSE),"")) -> 1260 | M43: =IF(OR(K43="",L43=""),"",IF(L43=0,"⚠ NO PARENT WIDTH",IF(K43>L43,"⚠ BABY > PARENT","✔ OK"))) -> ✔ OK | N43: =IF(D43="","",IF(COUNTIF(D$3:D43,D43)>1,"⚠ DUPLICATE","")) | O43: =IF(B43="","",SUMIF(B:B,B43,G:G)&" / "&IFERROR(VLOOKUP(B43,'Coil Sheet at Plant'!$C:$I,7,FALSE),"?")&" mm") -> 1259 / 1260 mm
A44: 46116 | B44: HYD-0426-06 | C44: A | D44: =IF(OR(B44="",C44=""),"",CONCATENATE(B44,"-",C44)) -> HYD-0426-06-A | E44: =IF(B44="","",IFERROR(VLOOKUP(B44,'Coil Sheet at Plant'!$C:$G,5,FALSE),"ID Not Found")) -> 2 | F44: =IF(B44="","",IFERROR(VLOOKUP(B44,'Coil Sheet at Plant'!$C:$H,6,FALSE),"ID Not Found")) | G44: 197 | H44: =IF(OR(B44="",G44=""),"",IFERROR(VLOOKUP(B44,'Coil Sheet at Plant'!$C:$J,8,FALSE),0)*G44/SUMIF(B:B,B44,G:G)) -> 3.4627562 | I44: =IF(B44="","",IFERROR(VLOOKUP(B44,'Coil Sheet at Plant'!$C:$L,9,FALSE),"")) -> 22.13 | J44: =IF(B44="","",IFERROR(VLOOKUP(B44,'Coil Sheet at Plant'!$C:$M,10,FALSE),"")) -> 13,01,244.0 | K44: =IF(B44="","",SUMIF(B:B,B44,G:G)) -> 1259 | L44: =IF(B44="","",IFERROR(VLOOKUP(B44,'Coil Sheet at Plant'!$C:$I,7,FALSE),"")) -> 1264 | M44: =IF(OR(K44="",L44=""),"",IF(L44=0,"⚠ NO PARENT WIDTH",IF(K44>L44,"⚠ BABY > PARENT","✔ OK"))) -> ✔ OK | N44: =IF(D44="","",IF(COUNTIF(D$3:D44,D44)>1,"⚠ DUPLICATE","")) | O44: =IF(B44="","",SUMIF(B:B,B44,G:G)&" / "&IFERROR(VLOOKUP(B44,'Coil Sheet at Plant'!$C:$I,7,FALSE),"?")&" mm") -> 1259 / 1264 mm
A45: 46116 | B45: HYD-0426-06 | C45: B | D45: =IF(OR(B45="",C45=""),"",CONCATENATE(B45,"-",C45)) -> HYD-0426-06-B | E45: =IF(B45="","",IFERROR(VLOOKUP(B45,'Coil Sheet at Plant'!$C:$G,5,FALSE),"ID Not Found")) -> 2 | F45: =IF(B45="","",IFERROR(VLOOKUP(B45,'Coil Sheet at Plant'!$C:$H,6,FALSE),"ID Not Found")) | G45: 197 | H45: =IF(OR(B45="",G45=""),"",IFERROR(VLOOKUP(B45,'Coil Sheet at Plant'!$C:$J,8,FALSE),0)*G45/SUMIF(B:B,B45,G:G)) -> 3.4627562 | I45: =IF(B45="","",IFERROR(VLOOKUP(B45,'Coil Sheet at Plant'!$C:$L,9,FALSE),"")) -> 22.13 | J45: =IF(B45="","",IFERROR(VLOOKUP(B45,'Coil Sheet at Plant'!$C:$M,10,FALSE),"")) -> 13,01,244.0 | K45: =IF(B45="","",SUMIF(B:B,B45,G:G)) -> 1259 | L45: =IF(B45="","",IFERROR(VLOOKUP(B45,'Coil Sheet at Plant'!$C:$I,7,FALSE),"")) -> 1264 | M45: =IF(OR(K45="",L45=""),"",IF(L45=0,"⚠ NO PARENT WIDTH",IF(K45>L45,"⚠ BABY > PARENT","✔ OK"))) -> ✔ OK | N45: =IF(D45="","",IF(COUNTIF(D$3:D45,D45)>1,"⚠ DUPLICATE","")) | O45: =IF(B45="","",SUMIF(B:B,B45,G:G)&" / "&IFERROR(VLOOKUP(B45,'Coil Sheet at Plant'!$C:$I,7,FALSE),"?")&" mm") -> 1259 / 1264 mm
A46: 46116 | B46: HYD-0426-06 | C46: C | D46: =IF(OR(B46="",C46=""),"",CONCATENATE(B46,"-",C46)) -> HYD-0426-06-C | E46: =IF(B46="","",IFERROR(VLOOKUP(B46,'Coil Sheet at Plant'!$C:$G,5,FALSE),"ID Not Found")) -> 2 | F46: =IF(B46="","",IFERROR(VLOOKUP(B46,'Coil Sheet at Plant'!$C:$H,6,FALSE),"ID Not Found")) | G46: 197 | H46: =IF(OR(B46="",G46=""),"",IFERROR(VLOOKUP(B46,'Coil Sheet at Plant'!$C:$J,8,FALSE),0)*G46/SUMIF(B:B,B46,G:G)) -> 3.4627562 | I46: =IF(B46="","",IFERROR(VLOOKUP(B46,'Coil Sheet at Plant'!$C:$L,9,FALSE),"")) -> 22.13 | J46: =IF(B46="","",IFERROR(VLOOKUP(B46,'Coil Sheet at Plant'!$C:$M,10,FALSE),"")) -> 13,01,244.0 | K46: =IF(B46="","",SUMIF(B:B,B46,G:G)) -> 1259 | L46: =IF(B46="","",IFERROR(VLOOKUP(B46,'Coil Sheet at Plant'!$C:$I,7,FALSE),"")) -> 1264 | M46: =IF(OR(K46="",L46=""),"",IF(L46=0,"⚠ NO PARENT WIDTH",IF(K46>L46,"⚠ BABY > PARENT","✔ OK"))) -> ✔ OK | N46: =IF(D46="","",IF(COUNTIF(D$3:D46,D46)>1,"⚠ DUPLICATE","")) | O46: =IF(B46="","",SUMIF(B:B,B46,G:G)&" / "&IFERROR(VLOOKUP(B46,'Coil Sheet at Plant'!$C:$I,7,FALSE),"?")&" mm") -> 1259 / 1264 mm
A47: 46116 | B47: HYD-0426-06 | C47: D | D47: =IF(OR(B47="",C47=""),"",CONCATENATE(B47,"-",C47)) -> HYD-0426-06-D | E47: =IF(B47="","",IFERROR(VLOOKUP(B47,'Coil Sheet at Plant'!$C:$G,5,FALSE),"ID Not Found")) -> 2 | F47: =IF(B47="","",IFERROR(VLOOKUP(B47,'Coil Sheet at Plant'!$C:$H,6,FALSE),"ID Not Found")) | G47: 197 | H47: =IF(OR(B47="",G47=""),"",IFERROR(VLOOKUP(B47,'Coil Sheet at Plant'!$C:$J,8,FALSE),0)*G47/SUMIF(B:B,B47,G:G)) -> 3.4627562 | I47: =IF(B47="","",IFERROR(VLOOKUP(B47,'Coil Sheet at Plant'!$C:$L,9,FALSE),"")) -> 22.13 | J47: =IF(B47="","",IFERROR(VLOOKUP(B47,'Coil Sheet at Plant'!$C:$M,10,FALSE),"")) -> 13,01,244.0 | K47: =IF(B47="","",SUMIF(B:B,B47,G:G)) -> 1259 | L47: =IF(B47="","",IFERROR(VLOOKUP(B47,'Coil Sheet at Plant'!$C:$I,7,FALSE),"")) -> 1264 | M47: =IF(OR(K47="",L47=""),"",IF(L47=0,"⚠ NO PARENT WIDTH",IF(K47>L47,"⚠ BABY > PARENT","✔ OK"))) -> ✔ OK | N47: =IF(D47="","",IF(COUNTIF(D$3:D47,D47)>1,"⚠ DUPLICATE","")) | O47: =IF(B47="","",SUMIF(B:B,B47,G:G)&" / "&IFERROR(VLOOKUP(B47,'Coil Sheet at Plant'!$C:$I,7,FALSE),"?")&" mm") -> 1259 / 1264 mm
A48: 46116 | B48: HYD-0426-06 | C48: E | D48: =IF(OR(B48="",C48=""),"",CONCATENATE(B48,"-",C48)) -> HYD-0426-06-E | E48: =IF(B48="","",IFERROR(VLOOKUP(B48,'Coil Sheet at Plant'!$C:$G,5,FALSE),"ID Not Found")) -> 2 | F48: =IF(B48="","",IFERROR(VLOOKUP(B48,'Coil Sheet at Plant'!$C:$H,6,FALSE),"ID Not Found")) | G48: 197 | H48: =IF(OR(B48="",G48=""),"",IFERROR(VLOOKUP(B48,'Coil Sheet at Plant'!$C:$J,8,FALSE),0)*G48/SUMIF(B:B,B48,G:G)) -> 3.4627562 | I48: =IF(B48="","",IFERROR(VLOOKUP(B48,'Coil Sheet at Plant'!$C:$L,9,FALSE),"")) -> 22.13 | J48: =IF(B48="","",IFERROR(VLOOKUP(B48,'Coil Sheet at Plant'!$C:$M,10,FALSE),"")) -> 13,01,244.0 | K48: =IF(B48="","",SUMIF(B:B,B48,G:G)) -> 1259 | L48: =IF(B48="","",IFERROR(VLOOKUP(B48,'Coil Sheet at Plant'!$C:$I,7,FALSE),"")) -> 1264 | M48: =IF(OR(K48="",L48=""),"",IF(L48=0,"⚠ NO PARENT WIDTH",IF(K48>L48,"⚠ BABY > PARENT","✔ OK"))) -> ✔ OK | N48: =IF(D48="","",IF(COUNTIF(D$3:D48,D48)>1,"⚠ DUPLICATE","")) | O48: =IF(B48="","",SUMIF(B:B,B48,G:G)&" / "&IFERROR(VLOOKUP(B48,'Coil Sheet at Plant'!$C:$I,7,FALSE),"?")&" mm") -> 1259 / 1264 mm
... A56: 46118 | B56: HYD-0426-07 | C56: F | D56: =IF(OR(B56="",C56=""),"",CONCATENATE(B56,"-",C56)) -> HYD-0426-07-F | E56: =IF(B56="","",IFERROR(VLOOKUP(B56,'Coil Sheet at Plant'!$C:$G,5,FALSE),"ID Not Found")) -> 2 | F56: =IF(B56="","",IFERROR(VLOOKUP(B56,'Coil Sheet at Plant'!$C:$H,6,FALSE),"ID Not Found")) | G56: 97 | H56: =IF(OR(B56="",G56=""),"",IFERROR(VLOOKUP(B56,'Coil Sheet at Plant'!$C:$J,8,FALSE),0)*G56/SUMIF(B:B,B56,G:G)) -> 1.4813015 | I56: =IF(B56="","",IFERROR(VLOOKUP(B56,'Coil Sheet at Plant'!$C:$L,9,FALSE),"")) -> 14.08 | J56: =IF(B56="","",IFERROR(VLOOKUP(B56,'Coil Sheet at Plant'!$C:$M,10,FALSE),"")) -> 8,37,760.00 | K56: =IF(B56="","",SUMIF(B:B,B56,G:G)) -> 922 | L56: =IF(B56="","",IFERROR(VLOOKUP(B56,'Coil Sheet at Plant'!$C:$I,7,FALSE),"")) -> 930 | M56: =IF(OR(K56="",L56=""),"",IF(L56=0,"⚠ NO PARENT WIDTH",IF(K56>L56,"⚠ BABY > PARENT","✔ OK"))) -> ✔ OK | N56: =IF(D56="","",IF(COUNTIF(D$3:D56,D56)>1,"⚠ DUPLICATE","")) | O56: =IF(B56="","",SUMIF(B:B,B56,G:G)&" / "&IFERROR(VLOOKUP(B56,'Coil Sheet at Plant'!$C:$I,7,FALSE),"?")&" mm") -> 922 / 930 mm
D57: =IF(OR(B57="",C57=""),"",CONCATENATE(B57,"-",C57)) | E57: =IF(B57="","",IFERROR(VLOOKUP(B57,'Coil Sheet at Plant'!$C:$G,5,FALSE),"ID Not Found")) | F57: =IF(B57="","",IFERROR(VLOOKUP(B57,'Coil Sheet at Plant'!$C:$H,6,FALSE),"ID Not Found")) | H57: =IF(OR(B57="",G57=""),"",IFERROR(VLOOKUP(B57,'Coil Sheet at Plant'!$C:$J,8,FALSE),0)*G57/SUMIF(B:B,B57,G:G)) | I57: =IF(B57="","",IFERROR(VLOOKUP(B57,'Coil Sheet at Plant'!$C:$L,9,FALSE),"")) | J57: =IF(B57="","",IFERROR(VLOOKUP(B57,'Coil Sheet at Plant'!$C:$M,10,FALSE),"")) | K57: =IF(B57="","",SUMIF(B:B,B57,G:G)) | L57: =IF(B57="","",IFERROR(VLOOKUP(B57,'Coil Sheet at Plant'!$C:$I,7,FALSE),"")) | M57: =IF(OR(K57="",L57=""),"",IF(L57=0,"⚠ NO PARENT WIDTH",IF(K57>L57,"⚠ BABY > PARENT","✔ OK"))) | N57: =IF(D57="","",IF(COUNTIF(D$3:D57,D57)>1,"⚠ DUPLICATE","")) | O57: =IF(B57="","",SUMIF(B:B,B57,G:G)&" / "&IFERROR(VLOOKUP(B57,'Coil Sheet at Plant'!$C:$I,7,FALSE),"?")&" mm")
D58: =IF(OR(B58="",C58=""),"",CONCATENATE(B58,"-",C58)) | E58: =IF(B58="","",IFERROR(VLOOKUP(B58,'Coil Sheet at Plant'!$C:$G,5,FALSE),"ID Not Found")) | F58: =IF(B58="","",IFERROR(VLOOKUP(B58,'Coil Sheet at Plant'!$C:$H,6,FALSE),"ID Not Found")) | H58: =IF(OR(B58="",G58=""),"",IFERROR(VLOOKUP(B58,'Coil Sheet at Plant'!$C:$J,8,FALSE),0)*G58/SUMIF(B:B,B58,G:G)) | I58: =IF(B58="","",IFERROR(VLOOKUP(B58,'Coil Sheet at Plant'!$C:$L,9,FALSE),"")) | J58: =IF(B58="","",IFERROR(VLOOKUP(B58,'Coil Sheet at Plant'!$C:$M,10,FALSE),"")) | K58: =IF(B58="","",SUMIF(B:B,B58,G:G)) | L58: =IF(B58="","",IFERROR(VLOOKUP(B58,'Coil Sheet at Plant'!$C:$I,7,FALSE),"")) | M58: =IF(OR(K58="",L58=""),"",IF(L58=0,"⚠ NO PARENT WIDTH",IF(K58>L58,"⚠ BABY > PARENT","✔ OK"))) | N58: =IF(D58="","",IF(COUNTIF(D$3:D58,D58)>1,"⚠ DUPLICATE","")) | O58: =IF(B58="","",SUMIF(B:B,B58,G:G)&" / "&IFERROR(VLOOKUP(B58,'Coil Sheet at Plant'!$C:$I,7,FALSE),"?")&" mm")
D59: =IF(OR(B59="",C59=""),"",CONCATENATE(B59,"-",C59)) | E59: =IF(B59="","",IFERROR(VLOOKUP(B59,'Coil Sheet at Plant'!$C:$G,5,FALSE),"ID Not Found")) | F59: =IF(B59="","",IFERROR(VLOOKUP(B59,'Coil Sheet at Plant'!$C:$H,6,FALSE),"ID Not Found")) | H59: =IF(OR(B59="",G59=""),"",IFERROR(VLOOKUP(B59,'Coil Sheet at Plant'!$C:$J,8,FALSE),0)*G59/SUMIF(B:B,B59,G:G)) | I59: =IF(B59="","",IFERROR(VLOOKUP(B59,'Coil Sheet at Plant'!$C:$L,9,FALSE),"")) | J59: =IF(B59="","",IFERROR(VLOOKUP(B59,'Coil Sheet at Plant'!$C:$M,10,FALSE),"")) | K59: =IF(B59="","",SUMIF(B:B,B59,G:G)) | L59: =IF(B59="","",IFERROR(VLOOKUP(B59,'Coil Sheet at Plant'!$C:$I,7,FALSE),"")) | M59: =IF(OR(K59="",L59=""),"",IF(L59=0,"⚠ NO PARENT WIDTH",IF(K59>L59,"⚠ BABY > PARENT","✔ OK"))) | N59: =IF(D59="","",IF(COUNTIF(D$3:D59,D59)>1,"⚠ DUPLICATE","")) | O59: =IF(B59="","",SUMIF(B:B,B59,G:G)&" / "&IFERROR(VLOOKUP(B59,'Coil Sheet at Plant'!$C:$I,7,FALSE),"?")&" mm")
D60: =IF(OR(B60="",C60=""),"",CONCATENATE(B60,"-",C60)) | E60: =IF(B60="","",IFERROR(VLOOKUP(B60,'Coil Sheet at Plant'!$C:$G,5,FALSE),"ID Not Found")) | F60: =IF(B60="","",IFERROR(VLOOKUP(B60,'Coil Sheet at Plant'!$C:$H,6,FALSE),"ID Not Found")) | H60: =IF(OR(B60="",G60=""),"",IFERROR(VLOOKUP(B60,'Coil Sheet at Plant'!$C:$J,8,FALSE),0)*G60/SUMIF(B:B,B60,G:G)) | I60: =IF(B60="","",IFERROR(VLOOKUP(B60,'Coil Sheet at Plant'!$C:$L,9,FALSE),"")) | J60: =IF(B60="","",IFERROR(VLOOKUP(B60,'Coil Sheet at Plant'!$C:$M,10,FALSE),"")) | K60: =IF(B60="","",SUMIF(B:B,B60,G:G)) | L60: =IF(B60="","",IFERROR(VLOOKUP(B60,'Coil Sheet at Plant'!$C:$I,7,FALSE),"")) | M60: =IF(OR(K60="",L60=""),"",IF(L60=0,"⚠ NO PARENT WIDTH",IF(K60>L60,"⚠ BABY > PARENT","✔ OK"))) | N60: =IF(D60="","",IF(COUNTIF(D$3:D60,D60)>1,"⚠ DUPLICATE","")) | O60: =IF(B60="","",SUMIF(B:B,B60,G:G)&" / "&IFERROR(VLOOKUP(B60,'Coil Sheet at Plant'!$C:$I,7,FALSE),"?")&" mm")
...

Sheet Slit to Tube Conversion
A1: 🔵 Manual Entry | I1: 🟡 Validation Helpers
A2: Date of Conversion | B2: SKU Code | C2: Baby Coil ID | D2: Number of Pieces | E2: Length (mm) | F2: Width (mm) | G2: Thickness (mm) | H2: Theortical Weight (T) | I2: Mother Coil Wt (T) | J2: Sum Bundle Wt (T) | K2: Wt Validation | L2: Duplicate Bundle ID Check
A3: 46109 | B3: MS SHS One Helix IS 4923 YSt 210 Black 38x38x2.80x6000 | C3: HYD-0326-01-A | D3: 124 | E3: =IF(C3="","",IFERROR(VLOOKUP(C3,'Coil to Slit'!$D:$H,3,FALSE),"")) -> 0 | F3: =IF(C3="","",IFERROR(VLOOKUP(C3,'Coil to Slit'!$D:$H,4,FALSE),"")) -> 147 | G3: =IF(C3="","",IFERROR(VLOOKUP(C3,'Coil to Slit'!$D:$H,2,FALSE),"")) -> 2.8 | H3: =IF(OR(C3="",D3=""),"",IFERROR(VLOOKUP(C3,'Coil to Slit'!$D:$H,5,FALSE),"")) -> 2.4397506 | I3: =IF(C3="","",IFERROR(VLOOKUP(LEFT(C3,LEN(C3)-2),'Coil Sheet at Plant'!$C:$J,8,FALSE),"")) -> 20.63 | J3: =IF(C3="","",SUMIF(C:C,C3,H:H)) -> 2.4397506 | K3: =IF(OR(I3="",J3=""),"",IF(J3>I3,"⚠ BUNDLES > MOTHER COIL","✔ OK")) -> ✔ OK | L3: =IF(#REF!="","",IF(COUNTIF(#REF!,#REF!)>1,"⚠ DUPLICATE","")) -> #REF!
A4: 46109 | B4: MS SHS One Helix IS 4923 YSt 210 Black 38x38x2.80x6000 | C4: HYD-0326-01-B | D4: 124 | E4: =IF(C4="","",IFERROR(VLOOKUP(C4,'Coil to Slit'!$D:$H,3,FALSE),"")) -> 0 | F4: =IF(C4="","",IFERROR(VLOOKUP(C4,'Coil to Slit'!$D:$H,4,FALSE),"")) -> 147 | G4: =IF(C4="","",IFERROR(VLOOKUP(C4,'Coil to Slit'!$D:$H,2,FALSE),"")) -> 2.8 | H4: =IF(OR(C4="",D4=""),"",IFERROR(VLOOKUP(C4,'Coil to Slit'!$D:$H,5,FALSE),"")) -> 2.4397506 | I4: =IF(C4="","",IFERROR(VLOOKUP(LEFT(C4,LEN(C4)-2),'Coil Sheet at Plant'!$C:$J,8,FALSE),"")) -> 20.63 | J4: =IF(C4="","",SUMIF(C:C,C4,H:H)) -> 2.4397506 | K4: =IF(OR(I4="",J4=""),"",IF(J4>I4,"⚠ BUNDLES > MOTHER COIL","✔ OK")) -> ✔ OK | L4: =IF(#REF!="","",IF(COUNTIF(#REF!,#REF!)>1,"⚠ DUPLICATE","")) -> #REF!
A5: 46111 | B5: MS SHS One Helix IS 4923 YSt 210 Black 38x38x2.80x6000 | C5: HYD-0326-01-C | D5: 126 | E5: =IF(C5="","",IFERROR(VLOOKUP(C5,'Coil to Slit'!$D:$H,3,FALSE),"")) -> 0 | F5: =IF(C5="","",IFERROR(VLOOKUP(C5,'Coil to Slit'!$D:$H,4,FALSE),"")) -> 147 | G5: =IF(C5="","",IFERROR(VLOOKUP(C5,'Coil to Slit'!$D:$H,2,FALSE),"")) -> 2.8 | H5: =IF(OR(C5="",D5=""),"",IFERROR(VLOOKUP(C5,'Coil to Slit'!$D:$H,5,FALSE),"")) -> 2.4397506 | I5: =IF(C5="","",IFERROR(VLOOKUP(LEFT(C5,LEN(C5)-2),'Coil Sheet at Plant'!$C:$J,8,FALSE),"")) -> 20.63 | J5: =IF(C5="","",SUMIF(C:C,C5,H:H)) -> 2.4397506 | K5: =IF(OR(I5="",J5=""),"",IF(J5>I5,"⚠ BUNDLES > MOTHER COIL","✔ OK")) -> ✔ OK | L5: =IF(#REF!="","",IF(COUNTIF(#REF!,#REF!)>1,"⚠ DUPLICATE","")) -> #REF!
A6: 46111 | B6: MS SHS One Helix IS 4923 YSt 210 Black 38x38x2.80x6000 | C6: HYD-0326-01-D | D6: 126 | E6: =IF(C6="","",IFERROR(VLOOKUP(C6,'Coil to Slit'!$D:$H,3,FALSE),"")) -> 0 | F6: =IF(C6="","",IFERROR(VLOOKUP(C6,'Coil to Slit'!$D:$H,4,FALSE),"")) -> 147 | G6: =IF(C6="","",IFERROR(VLOOKUP(C6,'Coil to Slit'!$D:$H,2,FALSE),"")) -> 2.8 | H6: =IF(OR(C6="",D6=""),"",IFERROR(VLOOKUP(C6,'Coil to Slit'!$D:$H,5,FALSE),"")) -> 2.4397506 | I6: =IF(C6="","",IFERROR(VLOOKUP(LEFT(C6,LEN(C6)-2),'Coil Sheet at Plant'!$C:$J,8,FALSE),"")) -> 20.63 | J6: =IF(C6="","",SUMIF(C:C,C6,H:H)) -> 2.4397506 | K6: =IF(OR(I6="",J6=""),"",IF(J6>I6,"⚠ BUNDLES > MOTHER COIL","✔ OK")) -> ✔ OK | L6: =IF(#REF!="","",IF(COUNTIF(#REF!,#REF!)>1,"⚠ DUPLICATE","")) -> #REF!
A7: 46111 | B7: MS SHS One Helix IS 4923 YSt 210 Black 38x38x2.80x6000 | C7: HYD-0326-01-E | D7: 128 | E7: =IF(C7="","",IFERROR(VLOOKUP(C7,'Coil to Slit'!$D:$H,3,FALSE),"")) -> 0 | F7: =IF(C7="","",IFERROR(VLOOKUP(C7,'Coil to Slit'!$D:$H,4,FALSE),"")) -> 147 | G7: =IF(C7="","",IFERROR(VLOOKUP(C7,'Coil to Slit'!$D:$H,2,FALSE),"")) -> 2.8 | H7: =IF(OR(C7="",D7=""),"",IFERROR(VLOOKUP(C7,'Coil to Slit'!$D:$H,5,FALSE),"")) -> 2.4397506 | I7: =IF(C7="","",IFERROR(VLOOKUP(LEFT(C7,LEN(C7)-2),'Coil Sheet at Plant'!$C:$J,8,FALSE),"")) -> 20.63 | J7: =IF(C7="","",SUMIF(C:C,C7,H:H)) -> 2.4397506 | K7: =IF(OR(I7="",J7=""),"",IF(J7>I7,"⚠ BUNDLES > MOTHER COIL","✔ OK")) -> ✔ OK | L7: =IF(#REF!="","",IF(COUNTIF(#REF!,#REF!)>1,"⚠ DUPLICATE","")) -> #REF!
A8: 46111 | B8: MS SHS One Helix IS 4923 YSt 210 Black 38x38x2.80x6000 | C8: HYD-0326-02-A | D8: 127 | E8: =IF(C8="","",IFERROR(VLOOKUP(C8,'Coil to Slit'!$D:$H,3,FALSE),"")) -> 0 | F8: =IF(C8="","",IFERROR(VLOOKUP(C8,'Coil to Slit'!$D:$H,4,FALSE),"")) -> 147 | G8: =IF(C8="","",IFERROR(VLOOKUP(C8,'Coil to Slit'!$D:$H,2,FALSE),"")) -> 2.8 | H8: =IF(OR(C8="",D8=""),"",IFERROR(VLOOKUP(C8,'Coil to Slit'!$D:$H,5,FALSE),"")) -> 2.4752293 | I8: =IF(C8="","",IFERROR(VLOOKUP(LEFT(C8,LEN(C8)-2),'Coil Sheet at Plant'!$C:$J,8,FALSE),"")) -> 20.93 | J8: =IF(C8="","",SUMIF(C:C,C8,H:H)) -> 2.4752293 | K8: =IF(OR(I8="",J8=""),"",IF(J8>I8,"⚠ BUNDLES > MOTHER COIL","✔ OK")) -> ✔ OK | L8: =IF(#REF!="","",IF(COUNTIF(#REF!,#REF!)>1,"⚠ DUPLICATE","")) -> #REF!
A9: 46111 | B9: MS SHS One Helix IS 4923 YSt 210 Black 38x38x2.80x6000 | C9: HYD-0326-02-B | D9: 127 | E9: =IF(C9="","",IFERROR(VLOOKUP(C9,'Coil to Slit'!$D:$H,3,FALSE),"")) -> 0 | F9: =IF(C9="","",IFERROR(VLOOKUP(C9,'Coil to Slit'!$D:$H,4,FALSE),"")) -> 147 | G9: =IF(C9="","",IFERROR(VLOOKUP(C9,'Coil to Slit'!$D:$H,2,FALSE),"")) -> 2.8 | H9: =IF(OR(C9="",D9=""),"",IFERROR(VLOOKUP(C9,'Coil to Slit'!$D:$H,5,FALSE),"")) -> 2.4752293 | I9: =IF(C9="","",IFERROR(VLOOKUP(LEFT(C9,LEN(C9)-2),'Coil Sheet at Plant'!$C:$J,8,FALSE),"")) -> 20.93 | J9: =IF(C9="","",SUMIF(C:C,C9,H:H)) -> 2.4752293 | K9: =IF(OR(I9="",J9=""),"",IF(J9>I9,"⚠ BUNDLES > MOTHER COIL","✔ OK")) -> ✔ OK | L9: =IF(#REF!="","",IF(COUNTIF(#REF!,#REF!)>1,"⚠ DUPLICATE","")) -> #REF!
A10: 46111 | B10: MS SHS One Helix IS 4923 YSt 210 Black 38x38x2.80x6000 | C10: HYD-0326-02-C | D10: 127 | E10: =IF(C10="","",IFERROR(VLOOKUP(C10,'Coil to Slit'!$D:$H,3,FALSE),"")) -> 0 | F10: =IF(C10="","",IFERROR(VLOOKUP(C10,'Coil to Slit'!$D:$H,4,FALSE),"")) -> 147 | G10: =IF(C10="","",IFERROR(VLOOKUP(C10,'Coil to Slit'!$D:$H,2,FALSE),"")) -> 2.8 | H10: =IF(OR(C10="",D10=""),"",IFERROR(VLOOKUP(C10,'Coil to Slit'!$D:$H,5,FALSE),"")) -> 2.4752293 | I10: =IF(C10="","",IFERROR(VLOOKUP(LEFT(C10,LEN(C10)-2),'Coil Sheet at Plant'!$C:$J,8,FALSE),"")) -> 20.93 | J10: =IF(C10="","",SUMIF(C:C,C10,H:H)) -> 2.4752293 | K10: =IF(OR(I10="",J10=""),"",IF(J10>I10,"⚠ BUNDLES > MOTHER COIL","✔ OK")) -> ✔ OK | L10: =IF(#REF!="","",IF(COUNTIF(#REF!,#REF!)>1,"⚠ DUPLICATE","")) -> #REF!
A11: 46111 | B11: MS SHS One Helix IS 4923 YSt 210 Black 38x38x2.80x6000 | C11: HYD-0326-02-D | D11: 127 | E11: =IF(C11="","",IFERROR(VLOOKUP(C11,'Coil to Slit'!$D:$H,3,FALSE),"")) -> 0 | F11: =IF(C11="","",IFERROR(VLOOKUP(C11,'Coil to Slit'!$D:$H,4,FALSE),"")) -> 147 | G11: =IF(C11="","",IFERROR(VLOOKUP(C11,'Coil to Slit'!$D:$H,2,FALSE),"")) -> 2.8 | H11: =IF(OR(C11="",D11=""),"",IFERROR(VLOOKUP(C11,'Coil to Slit'!$D:$H,5,FALSE),"")) -> 2.4752293 | I11: =IF(C11="","",IFERROR(VLOOKUP(LEFT(C11,LEN(C11)-2),'Coil Sheet at Plant'!$C:$J,8,FALSE),"")) -> 20.93 | J11: =IF(C11="","",SUMIF(C:C,C11,H:H)) -> 2.4752293 | K11: =IF(OR(I11="",J11=""),"",IF(J11>I11,"⚠ BUNDLES > MOTHER COIL","✔ OK")) -> ✔ OK | L11: =IF(#REF!="","",IF(COUNTIF(#REF!,#REF!)>1,"⚠ DUPLICATE","")) -> #REF!
A12: 46111 | B12: MS SHS One Helix IS 4923 YSt 210 Black 38x38x2.80x6000 | C12: HYD-0326-02-E | D12: 130 | E12: =IF(C12="","",IFERROR(VLOOKUP(C12,'Coil to Slit'!$D:$H,3,FALSE),"")) -> 0 | F12: =IF(C12="","",IFERROR(VLOOKUP(C12,'Coil to Slit'!$D:$H,4,FALSE),"")) -> 147 | G12: =IF(C12="","",IFERROR(VLOOKUP(C12,'Coil to Slit'!$D:$H,2,FALSE),"")) -> 2.8 | H12: =IF(OR(C12="",D12=""),"",IFERROR(VLOOKUP(C12,'Coil to Slit'!$D:$H,5,FALSE),"")) -> 2.4752293 | I12: =IF(C12="","",IFERROR(VLOOKUP(LEFT(C12,LEN(C12)-2),'Coil Sheet at Plant'!$C:$J,8,FALSE),"")) -> 20.93 | J12: =IF(C12="","",SUMIF(C:C,C12,H:H)) -> 2.4752293 | K12: =IF(OR(I12="",J12=""),"",IF(J12>I12,"⚠ BUNDLES > MOTHER COIL","✔ OK")) -> ✔ OK | L12: =IF(#REF!="","",IF(COUNTIF(#REF!,#REF!)>1,"⚠ DUPLICATE","")) -> #REF!
A13: 46111 | B13: MS SHS One Helix IS 4923 YSt 210 Black 38x38x2.50x6000 | C13: HYD-0326-03-A | D13: 161 | E13: =IF(C13="","",IFERROR(VLOOKUP(C13,'Coil to Slit'!$D:$H,3,FALSE),"")) -> 0 | F13: =IF(C13="","",IFERROR(VLOOKUP(C13,'Coil to Slit'!$D:$H,4,FALSE),"")) -> 147 | G13: =IF(C13="","",IFERROR(VLOOKUP(C13,'Coil to Slit'!$D:$H,2,FALSE),"")) -> 2.5 | H13: =IF(OR(C13="",D13=""),"",IFERROR(VLOOKUP(C13,'Coil to Slit'!$D:$H,5,FALSE),"")) -> 2.8627859 | I13: =IF(C13="","",IFERROR(VLOOKUP(LEFT(C13,LEN(C13)-2),'Coil Sheet at Plant'!$C:$J,8,FALSE),"")) -> 29.29 | J13: =IF(C13="","",SUMIF(C:C,C13,H:H)) -> 2.8627859 | K13: =IF(OR(I13="",J13=""),"",IF(J13>I13,"⚠ BUNDLES > MOTHER COIL","✔ OK")) -> ✔ OK | L13: =IF(#REF!="","",IF(COUNTIF(#REF!,#REF!)>1,"⚠ DUPLICATE","")) -> #REF!
A14: 46111 | B14: MS SHS One Helix IS 4923 YSt 210 Black 38x38x2.50x6000 | C14: HYD-0326-03-B | D14: 161 | E14: =IF(C14="","",IFERROR(VLOOKUP(C14,'Coil to Slit'!$D:$H,3,FALSE),"")) -> 0 | F14: =IF(C14="","",IFERROR(VLOOKUP(C14,'Coil to Slit'!$D:$H,4,FALSE),"")) -> 147 | G14: =IF(C14="","",IFERROR(VLOOKUP(C14,'Coil to Slit'!$D:$H,2,FALSE),"")) -> 2.5 | H14: =IF(OR(C14="",D14=""),"",IFERROR(VLOOKUP(C14,'Coil to Slit'!$D:$H,5,FALSE),"")) -> 2.8627859 | I14: =IF(C14="","",IFERROR(VLOOKUP(LEFT(C14,LEN(C14)-2),'Coil Sheet at Plant'!$C:$J,8,FALSE),"")) -> 29.29 | J14: =IF(C14="","",SUMIF(C:C,C14,H:H)) -> 2.8627859 | K14: =IF(OR(I14="",J14=""),"",IF(J14>I14,"⚠ BUNDLES > MOTHER COIL","✔ OK")) -> ✔ OK | L14: =IF(#REF!="","",IF(COUNTIF(#REF!,#REF!)>1,"⚠ DUPLICATE","")) -> #REF!
... A23: 46112 | B23: MS SHS One Helix IS 4923 YSt 210 Black 50x50x2.80x6000 | C23: HYD-0326-02-G | D23: 125 | E23: =IF(C23="","",IFERROR(VLOOKUP(C23,'Coil to Slit'!$D:$H,3,FALSE),"")) -> 0 | F23: =IF(C23="","",IFERROR(VLOOKUP(C23,'Coil to Slit'!$D:$H,4,FALSE),"")) -> 196 | G23: =IF(C23="","",IFERROR(VLOOKUP(C23,'Coil to Slit'!$D:$H,2,FALSE),"")) -> 2.8 | H23: =IF(OR(C23="",D23=""),"",IFERROR(VLOOKUP(C23,'Coil to Slit'!$D:$H,5,FALSE),"")) -> 3.3003057 | I23: =IF(C23="","",IFERROR(VLOOKUP(LEFT(C23,LEN(C23)-2),'Coil Sheet at Plant'!$C:$J,8,FALSE),"")) -> 20.93 | J23: =IF(C23="","",SUMIF(C:C,C23,H:H)) -> 3.3003057 | K23: =IF(OR(I23="",J23=""),"",IF(J23>I23,"⚠ BUNDLES > MOTHER COIL","✔ OK")) -> ✔ OK | L23: =IF(#REF!="","",IF(COUNTIF(#REF!,#REF!)>1,"⚠ DUPLICATE","")) -> #REF!
