Workbook

Sheet Summary by plant
A1: FG ageing calibrated to plant FG sheets - by plant (29-Oct-2026)
A3: Plant | B3: System FG (MT) | C3: Plant FG, sheet rows (MT) | D3: Plant / system | E3: Calibrated 0-30 d | F3: Calibrated 31-60 d | G3: Calibrated 61-90 d | H3: Calibrated 90+ d | I3: Age unknown (not in system) | J3: Calibrated FG (MT) | K3: Calibrated over 60 d | L3: % over 60 d | M3: System over 60 d (before calibration) | N3: Plant sheet total as printed (MT)
A4: Hyderabad | B4: =SUMIF('Plant x size'!$A$5:$A$171,A4,'Plant x size'!$C$5:$C$171) -> 683.42497 | C4: =SUMIF('Plant x size'!$A$5:$A$171,A4,'Plant x size'!$D$5:$D$171) -> 643.432 | D4: =IF(B4>0,C4/B4,0) -> 0.94148156 | E4: =SUMIF('Plant x size'!$A$5:$A$171,A4,'Plant x size'!$K$5:$K$171) -> 325.27652 | F4: =SUMIF('Plant x size'!$A$5:$A$171,A4,'Plant x size'!$L$5:$L$171) -> 89.235477 | G4: =SUMIF('Plant x size'!$A$5:$A$171,A4,'Plant x size'!$M$5:$M$171) -> 14.464 | H4: =SUMIF('Plant x size'!$A$5:$A$171,A4,'Plant x size'!$N$5:$N$171) -> 205.72501 | I4: =SUMIF('Plant x size'!$A$5:$A$171,A4,'Plant x size'!$O$5:$O$171) -> 8.731 | J4: =SUMIF('Plant x size'!$A$5:$A$171,A4,'Plant x size'!$P$5:$P$171) -> 643.432 | K4: =SUMIF('Plant x size'!$A$5:$A$171,A4,'Plant x size'!$Q$5:$Q$171) -> 220.18901 | L4: =IF(J4>0,K4/J4,0) -> 0.34221022 | M4: =SUMIF('Plant x size'!$A$5:$A$171,A4,'Plant x size'!$I$5:$I$171)+SUMIF('Plant x size'!$A$5:$A$171,A4,'Plant x size'!$J$5:$J$171) -> 241.07717 | N4: 649.586
A5: Lepakshi | B5: =SUMIF('Plant x size'!$A$5:$A$171,A5,'Plant x size'!$C$5:$C$171) -> 327.4206 | C5: =SUMIF('Plant x size'!$A$5:$A$171,A5,'Plant x size'!$D$5:$D$171) -> 385.1 | D5: =IF(B5>0,C5/B5,0) -> 1.176163 | E5: =SUMIF('Plant x size'!$A$5:$A$171,A5,'Plant x size'!$K$5:$K$171) -> 287.3 | F5: =SUMIF('Plant x size'!$A$5:$A$171,A5,'Plant x size'!$L$5:$L$171) -> 80.1 | G5: =SUMIF('Plant x size'!$A$5:$A$171,A5,'Plant x size'!$M$5:$M$171) -> 0 | H5: =SUMIF('Plant x size'!$A$5:$A$171,A5,'Plant x size'!$N$5:$N$171) -> 0 | I5: =SUMIF('Plant x size'!$A$5:$A$171,A5,'Plant x size'!$O$5:$O$171) -> 17.7 | J5: =SUMIF('Plant x size'!$A$5:$A$171,A5,'Plant x size'!$P$5:$P$171) -> 385.1 | K5: =SUMIF('Plant x size'!$A$5:$A$171,A5,'Plant x size'!$Q$5:$Q$171) -> 0 | L5: =IF(J5>0,K5/J5,0) -> 0 | M5: =SUMIF('Plant x size'!$A$5:$A$171,A5,'Plant x size'!$I$5:$I$171)+SUMIF('Plant x size'!$A$5:$A$171,A5,'Plant x size'!$J$5:$J$171) -> 0 | N5: 385.1
A6: NPMD | B6: =SUMIF('Plant x size'!$A$5:$A$171,A6,'Plant x size'!$C$5:$C$171) -> 777.88655 | C6: =SUMIF('Plant x size'!$A$5:$A$171,A6,'Plant x size'!$D$5:$D$171) -> 775.2 | D6: =IF(B6>0,C6/B6,0) -> 0.99654634 | E6: =SUMIF('Plant x size'!$A$5:$A$171,A6,'Plant x size'!$K$5:$K$171) -> 653.24393 | F6: =SUMIF('Plant x size'!$A$5:$A$171,A6,'Plant x size'!$L$5:$L$171) -> 121.05607 | G6: =SUMIF('Plant x size'!$A$5:$A$171,A6,'Plant x size'!$M$5:$M$171) -> 0 | H6: =SUMIF('Plant x size'!$A$5:$A$171,A6,'Plant x size'!$N$5:$N$171) -> 0 | I6: =SUMIF('Plant x size'!$A$5:$A$171,A6,'Plant x size'!$O$5:$O$171) -> 0.9 | J6: =SUMIF('Plant x size'!$A$5:$A$171,A6,'Plant x size'!$P$5:$P$171) -> 775.2 | K6: =SUMIF('Plant x size'!$A$5:$A$171,A6,'Plant x size'!$Q$5:$Q$171) -> 0 | L6: =IF(J6>0,K6/J6,0) -> 0 | M6: =SUMIF('Plant x size'!$A$5:$A$171,A6,'Plant x size'!$I$5:$I$171)+SUMIF('Plant x size'!$A$5:$A$171,A6,'Plant x size'!$J$5:$J$171) -> 0 | N6: 775.2
A7: Tapi | B7: =SUMIF('Plant x size'!$A$5:$A$171,A7,'Plant x size'!$C$5:$C$171) -> 784.7645 | C7: =SUMIF('Plant x size'!$A$5:$A$171,A7,'Plant x size'!$D$5:$D$171) -> 827 | D7: =IF(B7>0,C7/B7,0) -> 1.0538193 | E7: =SUMIF('Plant x size'!$A$5:$A$171,A7,'Plant x size'!$K$5:$K$171) -> 731.33995 | F7: =SUMIF('Plant x size'!$A$5:$A$171,A7,'Plant x size'!$L$5:$L$171) -> 24.660049 | G7: =SUMIF('Plant x size'!$A$5:$A$171,A7,'Plant x size'!$M$5:$M$171) -> 0 | H7: =SUMIF('Plant x size'!$A$5:$A$171,A7,'Plant x size'!$N$5:$N$171) -> 0 | I7: =SUMIF('Plant x size'!$A$5:$A$171,A7,'Plant x size'!$O$5:$O$171) -> 71 | J7: =SUMIF('Plant x size'!$A$5:$A$171,A7,'Plant x size'!$P$5:$P$171) -> 827 | K7: =SUMIF('Plant x size'!$A$5:$A$171,A7,'Plant x size'!$Q$5:$Q$171) -> 0 | L7: =IF(J7>0,K7/J7,0) -> 0 | M7: =SUMIF('Plant x size'!$A$5:$A$171,A7,'Plant x size'!$I$5:$I$171)+SUMIF('Plant x size'!$A$5:$A$171,A7,'Plant x size'!$J$5:$J$171) -> 4.494248 | N7: 826
A8: All plants | B8: =SUM(B4:B7) -> 2573.4966 | C8: =SUM(C4:C7) -> 2630.732 | D8: =IF(B8>0,C8/B8,0) -> 1.0222403 | E8: =SUM(E4:E7) -> 1997.1604 | F8: =SUM(F4:F7) -> 315.05159 | G8: =SUM(G4:G7) -> 14.464 | H8: =SUM(H4:H7) -> 205.72501 | I8: =SUM(I4:I7) -> 98.331 | J8: =SUM(J4:J7) -> 2630.732 | K8: =SUM(K4:K7) -> 220.18901 | L8: =IF(J8>0,K8/J8,0) -> 0.083698761 | M8: =SUM(M4:M7) -> 245.57141 | N8: =SUM(N4:N7) -> 2635.886
A10: Notes
A11: Plant FG = the plants' own FG sheets of 29-Oct (Hyderabad, Tapi Surat, Lepakshi Mill 2, NPMD), quantity / balance column. They are taken as the real stock.
A12: Hyderabad: the sheet prints 649.586 but its 55 visible rows add to 643.432; the other 6.154 MT cannot be placed against a size and is left out of the calibration.
A13: Tapi: the sheet shows whole tonnes; its rows add to 827 against a printed 826 (rounding). Lepakshi's sheet is not titled; it is identified as Lepakshi from its sizes.
A14: NPMD: HR and CRFH lines of the same size are added together (the system does not split them). Hyderabad's "25.4OD" rows are matched to CHS 20 NB.
A15: Thickness is clubbed to the nearest of 1.6 / 2 / 2.5 / 3 / 4 / 5 / 6 mm on both sides (1.2 -> 1.6, 2.2 -> 2, 2.8 / 2.9 / 3.2 -> 3), as decided on 29-Oct.
A16: System FG: produced (tubes x SKU master weight per tube) minus invoiced, at the same plant, per size, never below 0; invoices use up the oldest production first and the rest is aged from its production date (Inventory Snapshot rules S1, S2, S10, with the clubbed size).
A17: Calibration: for each plant and size, every age bucket is multiplied by plant FG / system FG. Where the plant holds stock the system shows as nil, it cannot be aged and is shown as "Age unknown". Avg age and oldest batch are the system's and do not change with the ratio.
A18: A large ratio usually means production not yet entered, or entered or billed under another size code; it is not a weighing difference. Invoices are billed at the same master weight per piece as production (within 0.05% at every plant), and NPMD's system FG is only 2.7 MT above its sheet (0.7 MT before over-invoiced sizes are counted as 0).

Sheet Plant x size
A1: FG ageing calibrated to plant FG sheets - by plant and size (29-Oct-2026)
A2: System FG and FIFO ageing from the database (production to 28-Oct, invoices to 24-28 Oct by plant). Thickness clubbed to 1.6 / 2 / 2.5 / 3 / 4 / 5 / 6. Each size is calibrated to the plant sheet: ratio = plant FG / system FG, and every age bucket is multiplied by it. Plant stock the system shows as nil is "Age unknown".
A4: Plant | B4: Size | C4: System FG (MT) | D4: Plant FG (MT) | E4: Ratio plant / system | F4: Status | G4: System 0-30 d | H4: System 31-60 d | I4: System 61-90 d | J4: System 90+ d | K4: Calibrated 0-30 d | L4: Calibrated 31-60 d | M4: Calibrated 61-90 d | N4: Calibrated 90+ d | O4: Age unknown (not in system) | P4: Calibrated FG (MT) | Q4: Calibrated over 60 d | R4: Avg age (days) | S4: Oldest batch (days) | T4: Last produced
A5: Hyderabad | B5: SHS 25x25 x 2 | C5: 12.312758 | D5: 11.749 | E5: =IF(C5>0,D5/C5,"") -> 0.95421354 | F5: =IF(AND(C5=0,D5>0),"Plant only",IF(AND(D5=0,C5>0),"System only",IF(ABS(D5-C5)<=0.5,"Match",IF(D5>C5,"Plant more","Plant less")))) -> Plant less | G5: 12.312758 | H5: 0 | I5: 0 | J5: 0 | K5: =IF(C5>0,G5*E5,0) -> 11.749 | L5: =IF(C5>0,H5*E5,0) -> 0 | M5: =IF(C5>0,I5*E5,0) -> 0 | N5: =IF(C5>0,J5*E5,0) -> 0 | O5: =IF(C5>0,0,D5) -> 0 | P5: =SUM(K5:O5) -> 11.749 | Q5: =M5+N5 -> 0 | R5: 11.484035 | S5: 28 | T5: 46315
A6: Hyderabad | B6: SHS 25x25 x 3 | C6: 0 | D6: 3.589 | E6: =IF(C6>0,D6/C6,"") | F6: =IF(AND(C6=0,D6>0),"Plant only",IF(AND(D6=0,C6>0),"System only",IF(ABS(D6-C6)<=0.5,"Match",IF(D6>C6,"Plant more","Plant less")))) -> Plant only | G6: 0 | H6: 0 | I6: 0 | J6: 0 | K6: =IF(C6>0,G6*E6,0) -> 0 | L6: =IF(C6>0,H6*E6,0) -> 0 | M6: =IF(C6>0,I6*E6,0) -> 0 | N6: =IF(C6>0,J6*E6,0) -> 0 | O6: =IF(C6>0,0,D6) -> 3.589 | P6: =SUM(K6:O6) -> 3.589 | Q6: =M6+N6 -> 0 | T6: 46298
A7: Hyderabad | B7: SHS 30x30 x 1.6 | C7: 0.39890797 | D7: 0 | E7: =IF(C7>0,D7/C7,"") -> 0 | F7: =IF(AND(C7=0,D7>0),"Plant only",IF(AND(D7=0,C7>0),"System only",IF(ABS(D7-C7)<=0.5,"Match",IF(D7>C7,"Plant more","Plant less")))) -> System only | G7: 0 | H7: 0 | I7: 0.39890797 | J7: 0 | K7: =IF(C7>0,G7*E7,0) -> 0 | L7: =IF(C7>0,H7*E7,0) -> 0 | M7: =IF(C7>0,I7*E7,0) -> 0 | N7: =IF(C7>0,J7*E7,0) -> 0 | O7: =IF(C7>0,0,D7) -> 0 | P7: =SUM(K7:O7) -> 0 | Q7: =M7+N7 -> 0 | R7: 71 | S7: 71 | T7: 46253
A8: Hyderabad | B8: SHS 30x30 x 2.5 | C8: 3.4545625 | D8: 3.03 | E8: =IF(C8>0,D8/C8,"") -> 0.87710094 | F8: =IF(AND(C8=0,D8>0),"Plant only",IF(AND(D8=0,C8>0),"System only",IF(ABS(D8-C8)<=0.5,"Match",IF(D8>C8,"Plant more","Plant less")))) -> Match | G8: 1.0232475 | H8: 0 | I8: 0 | J8: 2.431315 | K8: =IF(C8>0,G8*E8,0) -> 0.89749134 | L8: =IF(C8>0,H8*E8,0) -> 0 | M8: =IF(C8>0,I8*E8,0) -> 0 | N8: =IF(C8>0,J8*E8,0) -> 2.1325087 | O8: =IF(C8>0,0,D8) -> 0 | P8: =SUM(K8:O8) -> 3.03 | Q8: =M8+N8 -> 2.1325087 | R8: 85.083622 | S8: 115 | T8: 46310
A9: Hyderabad | B9: SHS 38x38 x 1.6 | C9: 1.1760019 | D9: 0 | E9: =IF(C9>0,D9/C9,"") -> 0 | F9: =IF(AND(C9=0,D9>0),"Plant only",IF(AND(D9=0,C9>0),"System only",IF(ABS(D9-C9)<=0.5,"Match",IF(D9>C9,"Plant more","Plant less")))) -> System only | G9: 1.1760019 | H9: 0 | I9: 0 | J9: 0 | K9: =IF(C9>0,G9*E9,0) -> 0 | L9: =IF(C9>0,H9*E9,0) -> 0 | M9: =IF(C9>0,I9*E9,0) -> 0 | N9: =IF(C9>0,J9*E9,0) -> 0 | O9: =IF(C9>0,0,D9) -> 0 | P9: =SUM(K9:O9) -> 0 | Q9: =M9+N9 -> 0 | R9: 24 | S9: 24 | T9: 46300
A10: Hyderabad | B10: SHS 38x38 x 2 | C10: 31.99696 | D10: 34.503 | E10: =IF(C10>0,D10/C10,"") -> 1.0783212 | F10: =IF(AND(C10=0,D10>0),"Plant only",IF(AND(D10=0,C10>0),"System only",IF(ABS(D10-C10)<=0.5,"Match",IF(D10>C10,"Plant more","Plant less")))) -> Plant more | G10: 31.99696 | H10: 0 | I10: 0 | J10: 0 | K10: =IF(C10>0,G10*E10,0) -> 34.503 | L10: =IF(C10>0,H10*E10,0) -> 0 | M10: =IF(C10>0,I10*E10,0) -> 0 | N10: =IF(C10>0,J10*E10,0) -> 0 | O10: =IF(C10>0,0,D10) -> 0 | P10: =SUM(K10:O10) -> 34.503 | Q10: =M10+N10 -> 0 | R10: 5.2881993 | S10: 23 | T10: 46323
A11: Hyderabad | B11: SHS 38x38 x 2.5 | C11: 23.161798 | D11: 19.677 | E11: =IF(C11>0,D11/C11,"") -> 0.84954545 | F11: =IF(AND(C11=0,D11>0),"Plant only",IF(AND(D11=0,C11>0),"System only",IF(ABS(D11-C11)<=0.5,"Match",IF(D11>C11,"Plant more","Plant less")))) -> Plant less | G11: 20.131482 | H11: 3.030316 | I11: 0 | J11: 0 | K11: =IF(C11>0,G11*E11,0) -> 17.102609 | L11: =IF(C11>0,H11*E11,0) -> 2.5743912 | M11: =IF(C11>0,I11*E11,0) -> 0 | N11: =IF(C11>0,J11*E11,0) -> 0 | O11: =IF(C11>0,0,D11) -> 0 | P11: =SUM(K11:O11) -> 19.677 | Q11: =M11+N11 -> 0 | R11: 6.9716351 | S11: 40 | T11: 46322
A12: Hyderabad | B12: SHS 38x38 x 3 | C12: 8.1270124 | D12: 13.237 | E12: =IF(C12>0,D12/C12,"") -> 1.6287658 | F12: =IF(AND(C12=0,D12>0),"Plant only",IF(AND(D12=0,C12>0),"System only",IF(ABS(D12-C12)<=0.5,"Match",IF(D12>C12,"Plant more","Plant less")))) -> Plant more | G12: 0 | H12: 8.1270124 | I12: 0 | J12: 0 | K12: =IF(C12>0,G12*E12,0) -> 0 | L12: =IF(C12>0,H12*E12,0) -> 13.237 | M12: =IF(C12>0,I12*E12,0) -> 0 | N12: =IF(C12>0,J12*E12,0) -> 0 | O12: =IF(C12>0,0,D12) -> 0 | P12: =SUM(K12:O12) -> 13.237 | Q12: =M12+N12 -> 0 | R12: 40 | S12: 40 | T12: 46284
A13: Hyderabad | B13: SHS 38x38 x 4 | C13: 0.062 | D13: 0 | E13: =IF(C13>0,D13/C13,"") -> 0 | F13: =IF(AND(C13=0,D13>0),"Plant only",IF(AND(D13=0,C13>0),"System only",IF(ABS(D13-C13)<=0.5,"Match",IF(D13>C13,"Plant more","Plant less")))) -> System only | G13: 0 | H13: 0 | I13: 0 | J13: 0.062 | K13: =IF(C13>0,G13*E13,0) -> 0 | L13: =IF(C13>0,H13*E13,0) -> 0 | M13: =IF(C13>0,I13*E13,0) -> 0 | N13: =IF(C13>0,J13*E13,0) -> 0 | O13: =IF(C13>0,0,D13) -> 0 | P13: =SUM(K13:O13) -> 0 | Q13: =M13+N13 -> 0 | R13: 127 | S13: 127 | T13: 46197
A14: Hyderabad | B14: SHS 50x50 x 1.6 | C14: 7.2721564 | D14: 8.671 | E14: =IF(C14>0,D14/C14,"") -> 1.1923561 | F14: =IF(AND(C14=0,D14>0),"Plant only",IF(AND(D14=0,C14>0),"System only",IF(ABS(D14-C14)<=0.5,"Match",IF(D14>C14,"Plant more","Plant less")))) -> Plant more | G14: 7.2721564 | H14: 0 | I14: 0 | J14: 0 | K14: =IF(C14>0,G14*E14,0) -> 8.671 | L14: =IF(C14>0,H14*E14,0) -> 0 | M14: =IF(C14>0,I14*E14,0) -> 0 | N14: =IF(C14>0,J14*E14,0) -> 0 | O14: =IF(C14>0,0,D14) -> 0 | P14: =SUM(K14:O14) -> 8.671 | Q14: =M14+N14 -> 0 | R14: 22 | S14: 22 | T14: 46302
A15: Hyderabad | B15: SHS 50x50 x 2 | C15: 6.1201272 | D15: 8.472 | E15: =IF(C15>0,D15/C15,"") -> 1.384285 | F15: =IF(AND(C15=0,D15>0),"Plant only",IF(AND(D15=0,C15>0),"System only",IF(ABS(D15-C15)<=0.5,"Match",IF(D15>C15,"Plant more","Plant less")))) -> Plant more | G15: 6.1201272 | H15: 0 | I15: 0 | J15: 0 | K15: =IF(C15>0,G15*E15,0) -> 8.472 | L15: =IF(C15>0,H15*E15,0) -> 0 | M15: =IF(C15>0,I15*E15,0) -> 0 | N15: =IF(C15>0,J15*E15,0) -> 0 | O15: =IF(C15>0,0,D15) -> 0 | P15: =SUM(K15:O15) -> 8.472 | Q15: =M15+N15 -> 0 | R15: 22 | S15: 22 | T15: 46302
A16: Hyderabad | B16: SHS 50x50 x 2.5 | C16: 0.9191025 | D16: 1.371 | E16: =IF(C16>0,D16/C16,"") -> 1.4916726 | F16: =IF(AND(C16=0,D16>0),"Plant only",IF(AND(D16=0,C16>0),"System only",IF(ABS(D16-C16)<=0.5,"Match",IF(D16>C16,"Plant more","Plant less")))) -> Match | G16: 0 | H16: 0.9191025 | I16: 0 | J16: 0 | K16: =IF(C16>0,G16*E16,0) -> 0 | L16: =IF(C16>0,H16*E16,0) -> 1.371 | M16: =IF(C16>0,I16*E16,0) -> 0 | N16: =IF(C16>0,J16*E16,0) -> 0 | O16: =IF(C16>0,0,D16) -> 0 | P16: =SUM(K16:O16) -> 1.371 | Q16: =M16+N16 -> 0 | R16: 50 | S16: 50 | T16: 46274
A17: Hyderabad | B17: SHS 50x50 x 3 | C17: 0.72990282 | D17: 0 | E17: =IF(C17>0,D17/C17,"") -> 0 | F17: =IF(AND(C17=0,D17>0),"Plant only",IF(AND(D17=0,C17>0),"System only",IF(ABS(D17-C17)<=0.5,"Match",IF(D17>C17,"Plant more","Plant less")))) -> System only | G17: 0 | H17: 0.72990282 | I17: 0 | J17: 0 | K17: =IF(C17>0,G17*E17,0) -> 0 | L17: =IF(C17>0,H17*E17,0) -> 0 | M17: =IF(C17>0,I17*E17,0) -> 0 | N17: =IF(C17>0,J17*E17,0) -> 0 | O17: =IF(C17>0,0,D17) -> 0 | P17: =SUM(K17:O17) -> 0 | Q17: =M17+N17 -> 0 | R17: 50 | S17: 50 | T17: 46274
A18: Hyderabad | B18: SHS 50x50 x 4 | C18: 0.9923136 | D18: 1.397 | E18: =IF(C18>0,D18/C18,"") -> 1.4078211 | F18: =IF(AND(C18=0,D18>0),"Plant only",IF(AND(D18=0,C18>0),"System only",IF(ABS(D18-C18)<=0.5,"Match",IF(D18>C18,"Plant more","Plant less")))) -> Match | G18: 0 | H18: 0.9923136 | I18: 0 | J18: 0 | K18: =IF(C18>0,G18*E18,0) -> 0 | L18: =IF(C18>0,H18*E18,0) -> 1.397 | M18: =IF(C18>0,I18*E18,0) -> 0 | N18: =IF(C18>0,J18*E18,0) -> 0 | O18: =IF(C18>0,0,D18) -> 0 | P18: =SUM(K18:O18) -> 1.397 | Q18: =M18+N18 -> 0 | R18: 36 | S18: 36 | T18: 46288
... A23: Hyderabad | B23: RHS 40x20 x 2 | C23: 1.8300654 | D23: 0 | E23: =IF(C23>0,D23/C23,"") -> 0 | F23: =IF(AND(C23=0,D23>0),"Plant only",IF(AND(D23=0,C23>0),"System only",IF(ABS(D23-C23)<=0.5,"Match",IF(D23>C23,"Plant more","Plant less")))) -> System only | G23: 0 | H23: 1.8300654 | I23: 0 | J23: 0 | K23: =IF(C23>0,G23*E23,0) -> 0 | L23: =IF(C23>0,H23*E23,0) -> 0 | M23: =IF(C23>0,I23*E23,0) -> 0 | N23: =IF(C23>0,J23*E23,0) -> 0 | O23: =IF(C23>0,0,D23) -> 0 | P23: =SUM(K23:O23) -> 0 | Q23: =M23+N23 -> 0 | R23: 37 | S23: 37 | T23: 46287
A24: Hyderabad | B24: RHS 40x20 x 2.5 | C24: 0 | D24: 1.693 | E24: =IF(C24>0,D24/C24,"") | F24: =IF(AND(C24=0,D24>0),"Plant only",IF(AND(D24=0,C24>0),"System only",IF(ABS(D24-C24)<=0.5,"Match",IF(D24>C24,"Plant more","Plant less")))) -> Plant only | G24: 0 | H24: 0 | I24: 0 | J24: 0 | K24: =IF(C24>0,G24*E24,0) -> 0 | L24: =IF(C24>0,H24*E24,0) -> 0 | M24: =IF(C24>0,I24*E24,0) -> 0 | N24: =IF(C24>0,J24*E24,0) -> 0 | O24: =IF(C24>0,0,D24) -> 1.693 | P24: =SUM(K24:O24) -> 1.693 | Q24: =M24+N24 -> 0 | T24: 46309
A25: Hyderabad | B25: RHS 40x20 x 3 | C25: 10.190474 | D25: 10.988 | E25: =IF(C25>0,D25/C25,"") -> 1.0782619 | F25: =IF(AND(C25=0,D25>0),"Plant only",IF(AND(D25=0,C25>0),"System only",IF(ABS(D25-C25)<=0.5,"Match",IF(D25>C25,"Plant more","Plant less")))) -> Plant more | G25: 10.190474 | H25: 0 | I25: 0 | J25: 0 | K25: =IF(C25>0,G25*E25,0) -> 10.988 | L25: =IF(C25>0,H25*E25,0) -> 0 | M25: =IF(C25>0,I25*E25,0) -> 0 | N25: =IF(C25>0,J25*E25,0) -> 0 | O25: =IF(C25>0,0,D25) -> 0 | P25: =SUM(K25:O25) -> 10.988 | Q25: =M25+N25 -> 0 | R25: 15 | S25: 15 | T25: 46309
A26: Hyderabad | B26: RHS 50x25 x 2 | C26: 11.350928 | D26: 16.866 | E26: =IF(C26>0,D26/C26,"") -> 1.4858696 | F26: =IF(AND(C26=0,D26>0),"Plant only",IF(AND(D26=0,C26>0),"System only",IF(ABS(D26-C26)<=0.5,"Match",IF(D26>C26,"Plant more","Plant less")))) -> Plant more | G26: 11.350928 | H26: 0 | I26: 0 | J26: 0 | K26: =IF(C26>0,G26*E26,0) -> 16.866 | L26: =IF(C26>0,H26*E26,0) -> 0 | M26: =IF(C26>0,I26*E26,0) -> 0 | N26: =IF(C26>0,J26*E26,0) -> 0 | O26: =IF(C26>0,0,D26) -> 0 | P26: =SUM(K26:O26) -> 16.866 | Q26: =M26+N26 -> 0 | R26: 7 | S26: 7 | T26: 46317
A27: Hyderabad | B27: RHS 50x25 x 2.5 | C27: 1.93852 | D27: 0 | E27: =IF(C27>0,D27/C27,"") -> 0 | F27: =IF(AND(C27=0,D27>0),"Plant only",IF(AND(D27=0,C27>0),"System only",IF(ABS(D27-C27)<=0.5,"Match",IF(D27>C27,"Plant more","Plant less")))) -> System only | G27: 0 | H27: 1.93852 | I27: 0 | J27: 0 | K27: =IF(C27>0,G27*E27,0) -> 0 | L27: =IF(C27>0,H27*E27,0) -> 0 | M27: =IF(C27>0,I27*E27,0) -> 0 | N27: =IF(C27>0,J27*E27,0) -> 0 | O27: =IF(C27>0,0,D27) -> 0 | P27: =SUM(K27:O27) -> 0 | Q27: =M27+N27 -> 0 | R27: 37 | S27: 37 | T27: 46287
A28: Hyderabad | B28: RHS 50x25 x 3 | C28: 1.492844 | D28: 0 | E28: =IF(C28>0,D28/C28,"") -> 0 | F28: =IF(AND(C28=0,D28>0),"Plant only",IF(AND(D28=0,C28>0),"System only",IF(ABS(D28-C28)<=0.5,"Match",IF(D28>C28,"Plant more","Plant less")))) -> System only | G28: 0 | H28: 0 | I28: 0 | J28: 1.492844 | K28: =IF(C28>0,G28*E28,0) -> 0 | L28: =IF(C28>0,H28*E28,0) -> 0 | M28: =IF(C28>0,I28*E28,0) -> 0 | N28: =IF(C28>0,J28*E28,0) -> 0 | O28: =IF(C28>0,0,D28) -> 0 | P28: =SUM(K28:O28) -> 0 | Q28: =M28+N28 -> 0 | R28: 162 | S28: 162 | T28: 46162
A29: Hyderabad | B29: RHS 60x40 x 1.6 | C29: 0.48009235 | D29: 0 | E29: =IF(C29>0,D29/C29,"") -> 0 | F29: =IF(AND(C29=0,D29>0),"Plant only",IF(AND(D29=0,C29>0),"System only",IF(ABS(D29-C29)<=0.5,"Match",IF(D29>C29,"Plant more","Plant less")))) -> System only | G29: 0.48009235 | H29: 0 | I29: 0 | J29: 0 | K29: =IF(C29>0,G29*E29,0) -> 0 | L29: =IF(C29>0,H29*E29,0) -> 0 | M29: =IF(C29>0,I29*E29,0) -> 0 | N29: =IF(C29>0,J29*E29,0) -> 0 | O29: =IF(C29>0,0,D29) -> 0 | P29: =SUM(K29:O29) -> 0 | Q29: =M29+N29 -> 0 | R29: 21 | S29: 21 | T29: 46303
A30: Hyderabad | B30: RHS 60x40 x 2 | C30: 20.686965 | D30: 22.891 | E30: =IF(C30>0,D30/C30,"") -> 1.1065422 | F30: =IF(AND(C30=0,D30>0),"Plant only",IF(AND(D30=0,C30>0),"System only",IF(ABS(D30-C30)<=0.5,"Match",IF(D30>C30,"Plant more","Plant less")))) -> Plant more | G30: 20.686965 | H30: 0 | I30: 0 | J30: 0 | K30: =IF(C30>0,G30*E30,0) -> 22.891 | L30: =IF(C30>0,H30*E30,0) -> 0 | M30: =IF(C30>0,I30*E30,0) -> 0 | N30: =IF(C30>0,J30*E30,0) -> 0 | O30: =IF(C30>0,0,D30) -> 0 | P30: =SUM(K30:O30) -> 22.891 | Q30: =M30+N30 -> 0 | R30: 10 | S30: 10 | T30: 46314
A31: Hyderabad | B31: RHS 60x40 x 2.5 | C31: 13.008468 | D31: 11.674 | E31: =IF(C31>0,D31/C31,"") -> 0.89741547 | F31: =IF(AND(C31=0,D31>0),"Plant only",IF(AND(D31=0,C31>0),"System only",IF(ABS(D31-C31)<=0.5,"Match",IF(D31>C31,"Plant more","Plant less")))) -> Plant less | G31: 0 | H31: 13.008468 | I31: 0 | J31: 0 | K31: =IF(C31>0,G31*E31,0) -> 0 | L31: =IF(C31>0,H31*E31,0) -> 11.674 | M31: =IF(C31>0,I31*E31,0) -> 0 | N31: =IF(C31>0,J31*E31,0) -> 0 | O31: =IF(C31>0,0,D31) -> 0 | P31: =SUM(K31:O31) -> 11.674 | Q31: =M31+N31 -> 0 | R31: 48 | S31: 48 | T31: 46276
A32: Hyderabad | B32: RHS 60x40 x 3 | C32: 22.62413 | D32: 16.966 | E32: =IF(C32>0,D32/C32,"") -> 0.74990727 | F32: =IF(AND(C32=0,D32>0),"Plant only",IF(AND(D32=0,C32>0),"System only",IF(ABS(D32-C32)<=0.5,"Match",IF(D32>C32,"Plant more","Plant less")))) -> Plant less | G32: 22.62413 | H32: 0 | I32: 0 | J32: 0 | K32: =IF(C32>0,G32*E32,0) -> 16.966 | L32: =IF(C32>0,H32*E32,0) -> 0 | M32: =IF(C32>0,I32*E32,0) -> 0 | N32: =IF(C32>0,J32*E32,0) -> 0 | O32: =IF(C32>0,0,D32) -> 0 | P32: =SUM(K32:O32) -> 16.966 | Q32: =M32+N32 -> 0 | R32: 18.101953 | S32: 19 | T32: 46307
A33: Hyderabad | B33: RHS 75x25 x 2 | C33: 9.5933392 | D33: 9.983 | E33: =IF(C33>0,D33/C33,"") -> 1.0406178 | F33: =IF(AND(C33=0,D33>0),"Plant only",IF(AND(D33=0,C33>0),"System only",IF(ABS(D33-C33)<=0.5,"Match",IF(D33>C33,"Plant more","Plant less")))) -> Match | G33: 0 | H33: 0 | I33: 0 | J33: 9.5933392 | K33: =IF(C33>0,G33*E33,0) -> 0 | L33: =IF(C33>0,H33*E33,0) -> 0 | M33: =IF(C33>0,I33*E33,0) -> 0 | N33: =IF(C33>0,J33*E33,0) -> 9.983 | O33: =IF(C33>0,0,D33) -> 0 | P33: =SUM(K33:O33) -> 9.983 | Q33: =M33+N33 -> 9.983 | R33: 187 | S33: 187 | T33: 46137
A34: Hyderabad | B34: RHS 75x25 x 2.5 | C34: 1.095805 | D34: 0 | E34: =IF(C34>0,D34/C34,"") -> 0 | F34: =IF(AND(C34=0,D34>0),"Plant only",IF(AND(D34=0,C34>0),"System only",IF(ABS(D34-C34)<=0.5,"Match",IF(D34>C34,"Plant more","Plant less")))) -> System only | G34: 0 | H34: 0 | I34: 0 | J34: 1.095805 | K34: =IF(C34>0,G34*E34,0) -> 0 | L34: =IF(C34>0,H34*E34,0) -> 0 | M34: =IF(C34>0,I34*E34,0) -> 0 | N34: =IF(C34>0,J34*E34,0) -> 0 | O34: =IF(C34>0,0,D34) -> 0 | P34: =SUM(K34:O34) -> 0 | Q34: =M34+N34 -> 0 | R34: 185 | S34: 185 | T34: 46139
A35: Hyderabad | B35: RHS 75x25 x 3 | C35: 20.024344 | D35: 18.573 | E35: =IF(C35>0,D35/C35,"") -> 0.92752104 | F35: =IF(AND(C35=0,D35>0),"Plant only",IF(AND(D35=0,C35>0),"System only",IF(ABS(D35-C35)<=0.5,"Match",IF(D35>C35,"Plant more","Plant less")))) -> Plant less | G35: 0 | H35: 0 | I35: 0 | J35: 20.024344 | K35: =IF(C35>0,G35*E35,0) -> 0 | L35: =IF(C35>0,H35*E35,0) -> 0 | M35: =IF(C35>0,I35*E35,0) -> 0 | N35: =IF(C35>0,J35*E35,0) -> 18.573 | O35: =IF(C35>0,0,D35) -> 0 | P35: =SUM(K35:O35) -> 18.573 | Q35: =M35+N35 -> 18.573 | R35: 188.05499 | S35: 189 | T35: 46139
A36: Hyderabad | B36: RHS 80x40 x 2 | C36: 35.758794 | D36: 28.752 | E36: =IF(C36>0,D36/C36,"") -> 0.80405397 | F36: =IF(AND(C36=0,D36>0),"Plant only",IF(AND(D36=0,C36>0),"System only",IF(ABS(D36-C36)<=0.5,"Match",IF(D36>C36,"Plant more","Plant less")))) -> Plant less | G36: 35.758794 | H36: 0 | I36: 0 | J36: 0 | K36: =IF(C36>0,G36*E36,0) -> 28.752 | L36: =IF(C36>0,H36*E36,0) -> 0 | M36: =IF(C36>0,I36*E36,0) -> 0 | N36: =IF(C36>0,J36*E36,0) -> 0 | O36: =IF(C36>0,0,D36) -> 0 | P36: =SUM(K36:O36) -> 28.752 | Q36: =M36+N36 -> 0 | R36: 15 | S36: 15 | T36: 46309
... A51: Hyderabad | B51: CHS 25 NB x 2.5 | C51: 0.2765439 | D51: 1.04 | E51: =IF(C51>0,D51/C51,"") -> 3.7607049 | F51: =IF(AND(C51=0,D51>0),"Plant only",IF(AND(D51=0,C51>0),"System only",IF(ABS(D51-C51)<=0.5,"Match",IF(D51>C51,"Plant more","Plant less")))) -> Plant more | G51: 0.2765439 | H51: 0 | I51: 0 | J51: 0 | K51: =IF(C51>0,G51*E51,0) -> 1.04 | L51: =IF(C51>0,H51*E51,0) -> 0 | M51: =IF(C51>0,I51*E51,0) -> 0 | N51: =IF(C51>0,J51*E51,0) -> 0 | O51: =IF(C51>0,0,D51) -> 0 | P51: =SUM(K51:O51) -> 1.04 | Q51: =M51+N51 -> 0 | R51: 26 | S51: 26 | T51: 46298
A52: Hyderabad | B52: CHS 25 NB x 3 | C52: 0 | D52: 3.449 | E52: =IF(C52>0,D52/C52,"") | F52: =IF(AND(C52=0,D52>0),"Plant only",IF(AND(D52=0,C52>0),"System only",IF(ABS(D52-C52)<=0.5,"Match",IF(D52>C52,"Plant more","Plant less")))) -> Plant only | G52: 0 | H52: 0 | I52: 0 | J52: 0 | K52: =IF(C52>0,G52*E52,0) -> 0 | L52: =IF(C52>0,H52*E52,0) -> 0 | M52: =IF(C52>0,I52*E52,0) -> 0 | N52: =IF(C52>0,J52*E52,0) -> 0 | O52: =IF(C52>0,0,D52) -> 3.449 | P52: =SUM(K52:O52) -> 3.449 | Q52: =M52+N52 -> 0 | T52: 46298
A53: Hyderabad | B53: CHS 32 NB x 1.6 | C53: 1.3504409 | D53: 0 | E53: =IF(C53>0,D53/C53,"") -> 0 | F53: =IF(AND(C53=0,D53>0),"Plant only",IF(AND(D53=0,C53>0),"System only",IF(ABS(D53-C53)<=0.5,"Match",IF(D53>C53,"Plant more","Plant less")))) -> System only | G53: 0 | H53: 1.3504409 | I53: 0 | J53: 0 | K53: =IF(C53>0,G53*E53,0) -> 0 | L53: =IF(C53>0,H53*E53,0) -> 0 | M53: =IF(C53>0,I53*E53,0) -> 0 | N53: =IF(C53>0,J53*E53,0) -> 0 | O53: =IF(C53>0,0,D53) -> 0 | P53: =SUM(K53:O53) -> 0 | Q53: =M53+N53 -> 0 | R53: 52 | S53: 52 | T53: 46272
A54: Hyderabad | B54: CHS 32 NB x 2 | C54: 7.3919667 | D54: 7.702 | E54: =IF(C54>0,D54/C54,"") -> 1.0419419 | F54: =IF(AND(C54=0,D54>0),"Plant only",IF(AND(D54=0,C54>0),"System only",IF(ABS(D54-C54)<=0.5,"Match",IF(D54>C54,"Plant more","Plant less")))) -> Match | G54: 0 | H54: 0 | I54: 7.3919667 | J54: 0 | K54: =IF(C54>0,G54*E54,0) -> 0 | L54: =IF(C54>0,H54*E54,0) -> 0 | M54: =IF(C54>0,I54*E54,0) -> 7.702 | N54: =IF(C54>0,J54*E54,0) -> 0 | O54: =IF(C54>0,0,D54) -> 0 | P54: =SUM(K54:O54) -> 7.702 | Q54: =M54+N54 -> 7.702 | R54: 71 | S54: 71 | T54: 46253
A55: Hyderabad | B55: CHS 32 NB x 2.5 | C55: 25.735566 | D55: 25.051 | E55: =IF(C55>0,D55/C55,"") -> 0.97339999 | F55: =IF(AND(C55=0,D55>0),"Plant only",IF(AND(D55=0,C55>0),"System only",IF(ABS(D55-C55)<=0.5,"Match",IF(D55>C55,"Plant more","Plant less")))) -> Plant less | G55: 4.2951336 | H55: 0 | I55: 0 | J55: 21.440433 | K55: =IF(C55>0,G55*E55,0) -> 4.180883 | L55: =IF(C55>0,H55*E55,0) -> 0 | M55: =IF(C55>0,I55*E55,0) -> 0 | N55: =IF(C55>0,J55*E55,0) -> 20.870117 | O55: =IF(C55>0,0,D55) -> 0 | P55: =SUM(K55:O55) -> 25.051 | Q55: =M55+N55 -> 20.870117 | R55: 95.645674 | S55: 111 | T55: 46305
A56: Hyderabad | B56: CHS 32 NB x 3 | C56: 2.3627734 | D56: 2.434 | E56: =IF(C56>0,D56/C56,"") -> 1.0301454 | F56: =IF(AND(C56=0,D56>0),"Plant only",IF(AND(D56=0,C56>0),"System only",IF(ABS(D56-C56)<=0.5,"Match",IF(D56>C56,"Plant more","Plant less")))) -> Match | G56: 2.3627734 | H56: 0 | I56: 0 | J56: 0 | K56: =IF(C56>0,G56*E56,0) -> 2.434 | L56: =IF(C56>0,H56*E56,0) -> 0 | M56: =IF(C56>0,I56*E56,0) -> 0 | N56: =IF(C56>0,J56*E56,0) -> 0 | O56: =IF(C56>0,0,D56) -> 0 | P56: =SUM(K56:O56) -> 2.434 | Q56: =M56+N56 -> 0 | R56: 19 | S56: 19 | T56: 46305
A57: Hyderabad | B57: CHS 40 NB x 2 | C57: 24.631153 | D57: 25.549 | E57: =IF(C57>0,D57/C57,"") -> 1.0372637 | F57: =IF(AND(C57=0,D57>0),"Plant only",IF(AND(D57=0,C57>0),"System only",IF(ABS(D57-C57)<=0.5,"Match",IF(D57>C57,"Plant more","Plant less")))) -> Plant more | G57: 0 | H57: 20.525492 | I57: 0 | J57: 4.1056604 | K57: =IF(C57>0,G57*E57,0) -> 0 | L57: =IF(C57>0,H57*E57,0) -> 21.290348 | M57: =IF(C57>0,I57*E57,0) -> 0 | N57: =IF(C57>0,J57*E57,0) -> 4.2586524 | O57: =IF(C57>0,0,D57) -> 0 | P57: =SUM(K57:O57) -> 25.549 | Q57: =M57+N57 -> 4.2586524 | R57: 49.001255 | S57: 104 | T57: 46286
A58: Hyderabad | B58: CHS 40 NB x 2.5 | C58: 1.1016648 | D58: 0 | E58: =IF(C58>0,D58/C58,"") -> 0 | F58: =IF(AND(C58=0,D58>0),"Plant only",IF(AND(D58=0,C58>0),"System only",IF(ABS(D58-C58)<=0.5,"Match",IF(D58>C58,"Plant more","Plant less")))) -> System only | G58: 0 | H58: 0 | I58: 0 | J58: 1.1016648 | K58: =IF(C58>0,G58*E58,0) -> 0 | L58: =IF(C58>0,H58*E58,0) -> 0 | M58: =IF(C58>0,I58*E58,0) -> 0 | N58: =IF(C58>0,J58*E58,0) -> 0 | O58: =IF(C58>0,0,D58) -> 0 | P58: =SUM(K58:O58) -> 0 | Q58: =M58+N58 -> 0 | R58: 131 | S58: 131 | T58: 46193
A59: Hyderabad | B59: CHS 40 NB x 3 | C59: 0.24314298 | D59: 0 | E59: =IF(C59>0,D59/C59,"") -> 0 | F59: =IF(AND(C59=0,D59>0),"Plant only",IF(AND(D59=0,C59>0),"System only",IF(ABS(D59-C59)<=0.5,"Match",IF(D59>C59,"Plant more","Plant less")))) -> System only | G59: 0 | H59: 0.24314298 | I59: 0 | J59: 0 | K59: =IF(C59>0,G59*E59,0) -> 0 | L59: =IF(C59>0,H59*E59,0) -> 0 | M59: =IF(C59>0,I59*E59,0) -> 0 | N59: =IF(C59>0,J59*E59,0) -> 0 | O59: =IF(C59>0,0,D59) -> 0 | P59: =SUM(K59:O59) -> 0 | Q59: =M59+N59 -> 0 | R59: 38 | S59: 38 | T59: 46286
...

Sheet SKU-wise all plants
A1: FG ageing calibrated - SKU-wise, all plants (29-Oct-2026)
A3: Size | B3: System FG (MT) | C3: Plant FG (MT) | D3: Calibrated 0-30 d | E3: Calibrated 31-60 d | F3: Calibrated 61-90 d | G3: Calibrated 90+ d | H3: Age unknown (not in system) | I3: Calibrated FG (MT) | J3: Calibrated over 60 d | K3: Hyderabad | L3: Lepakshi | M3: NPMD | N3: Tapi
A4: SHS 25x25 x 2 | B4: =SUMIF('Plant x size'!$B$5:$B$171,A4,'Plant x size'!$C$5:$C$171) -> 12.312758 | C4: =SUMIF('Plant x size'!$B$5:$B$171,A4,'Plant x size'!$D$5:$D$171) -> 13.749 | D4: =SUMIF('Plant x size'!$B$5:$B$171,A4,'Plant x size'!$K$5:$K$171) -> 11.749 | E4: =SUMIF('Plant x size'!$B$5:$B$171,A4,'Plant x size'!$L$5:$L$171) -> 0 | F4: =SUMIF('Plant x size'!$B$5:$B$171,A4,'Plant x size'!$M$5:$M$171) -> 0 | G4: =SUMIF('Plant x size'!$B$5:$B$171,A4,'Plant x size'!$N$5:$N$171) -> 0 | H4: =SUMIF('Plant x size'!$B$5:$B$171,A4,'Plant x size'!$O$5:$O$171) -> 2 | I4: =SUMIF('Plant x size'!$B$5:$B$171,A4,'Plant x size'!$P$5:$P$171) -> 13.749 | J4: =SUMIF('Plant x size'!$B$5:$B$171,A4,'Plant x size'!$Q$5:$Q$171) -> 0 | K4: =SUMIFS('Plant x size'!$P$5:$P$171,'Plant x size'!$B$5:$B$171,A4,'Plant x size'!$A$5:$A$171,"Hyderabad") -> 11.749 | L4: =SUMIFS('Plant x size'!$P$5:$P$171,'Plant x size'!$B$5:$B$171,A4,'Plant x size'!$A$5:$A$171,"Lepakshi") -> 2 | M4: =SUMIFS('Plant x size'!$P$5:$P$171,'Plant x size'!$B$5:$B$171,A4,'Plant x size'!$A$5:$A$171,"NPMD") -> 0 | N4: =SUMIFS('Plant x size'!$P$5:$P$171,'Plant x size'!$B$5:$B$171,A4,'Plant x size'!$A$5:$A$171,"Tapi") -> 0
A5: SHS 25x25 x 2.5 | B5: =SUMIF('Plant x size'!$B$5:$B$171,A5,'Plant x size'!$C$5:$C$171) -> 0 | C5: =SUMIF('Plant x size'!$B$5:$B$171,A5,'Plant x size'!$D$5:$D$171) -> 4 | D5: =SUMIF('Plant x size'!$B$5:$B$171,A5,'Plant x size'!$K$5:$K$171) -> 0 | E5: =SUMIF('Plant x size'!$B$5:$B$171,A5,'Plant x size'!$L$5:$L$171) -> 0 | F5: =SUMIF('Plant x size'!$B$5:$B$171,A5,'Plant x size'!$M$5:$M$171) -> 0 | G5: =SUMIF('Plant x size'!$B$5:$B$171,A5,'Plant x size'!$N$5:$N$171) -> 0 | H5: =SUMIF('Plant x size'!$B$5:$B$171,A5,'Plant x size'!$O$5:$O$171) -> 4 | I5: =SUMIF('Plant x size'!$B$5:$B$171,A5,'Plant x size'!$P$5:$P$171) -> 4 | J5: =SUMIF('Plant x size'!$B$5:$B$171,A5,'Plant x size'!$Q$5:$Q$171) -> 0 | K5: =SUMIFS('Plant x size'!$P$5:$P$171,'Plant x size'!$B$5:$B$171,A5,'Plant x size'!$A$5:$A$171,"Hyderabad") -> 0 | L5: =SUMIFS('Plant x size'!$P$5:$P$171,'Plant x size'!$B$5:$B$171,A5,'Plant x size'!$A$5:$A$171,"Lepakshi") -> 4 | M5: =SUMIFS('Plant x size'!$P$5:$P$171,'Plant x size'!$B$5:$B$171,A5,'Plant x size'!$A$5:$A$171,"NPMD") -> 0 | N5: =SUMIFS('Plant x size'!$P$5:$P$171,'Plant x size'!$B$5:$B$171,A5,'Plant x size'!$A$5:$A$171,"Tapi") -> 0
A6: SHS 25x25 x 3 | B6: =SUMIF('Plant x size'!$B$5:$B$171,A6,'Plant x size'!$C$5:$C$171) -> 0 | C6: =SUMIF('Plant x size'!$B$5:$B$171,A6,'Plant x size'!$D$5:$D$171) -> 3.589 | D6: =SUMIF('Plant x size'!$B$5:$B$171,A6,'Plant x size'!$K$5:$K$171) -> 0 | E6: =SUMIF('Plant x size'!$B$5:$B$171,A6,'Plant x size'!$L$5:$L$171) -> 0 | F6: =SUMIF('Plant x size'!$B$5:$B$171,A6,'Plant x size'!$M$5:$M$171) -> 0 | G6: =SUMIF('Plant x size'!$B$5:$B$171,A6,'Plant x size'!$N$5:$N$171) -> 0 | H6: =SUMIF('Plant x size'!$B$5:$B$171,A6,'Plant x size'!$O$5:$O$171) -> 3.589 | I6: =SUMIF('Plant x size'!$B$5:$B$171,A6,'Plant x size'!$P$5:$P$171) -> 3.589 | J6: =SUMIF('Plant x size'!$B$5:$B$171,A6,'Plant x size'!$Q$5:$Q$171) -> 0 | K6: =SUMIFS('Plant x size'!$P$5:$P$171,'Plant x size'!$B$5:$B$171,A6,'Plant x size'!$A$5:$A$171,"Hyderabad") -> 3.589 | L6: =SUMIFS('Plant x size'!$P$5:$P$171,'Plant x size'!$B$5:$B$171,A6,'Plant x size'!$A$5:$A$171,"Lepakshi") -> 0 | M6: =SUMIFS('Plant x size'!$P$5:$P$171,'Plant x size'!$B$5:$B$171,A6,'Plant x size'!$A$5:$A$171,"NPMD") -> 0 | N6: =SUMIFS('Plant x size'!$P$5:$P$171,'Plant x size'!$B$5:$B$171,A6,'Plant x size'!$A$5:$A$171,"Tapi") -> 0
A7: SHS 30x30 x 1.6 | B7: =SUMIF('Plant x size'!$B$5:$B$171,A7,'Plant x size'!$C$5:$C$171) -> 0.39890797 | C7: =SUMIF('Plant x size'!$B$5:$B$171,A7,'Plant x size'!$D$5:$D$171) -> 0 | D7: =SUMIF('Plant x size'!$B$5:$B$171,A7,'Plant x size'!$K$5:$K$171) -> 0 | E7: =SUMIF('Plant x size'!$B$5:$B$171,A7,'Plant x size'!$L$5:$L$171) -> 0 | F7: =SUMIF('Plant x size'!$B$5:$B$171,A7,'Plant x size'!$M$5:$M$171) -> 0 | G7: =SUMIF('Plant x size'!$B$5:$B$171,A7,'Plant x size'!$N$5:$N$171) -> 0 | H7: =SUMIF('Plant x size'!$B$5:$B$171,A7,'Plant x size'!$O$5:$O$171) -> 0 | I7: =SUMIF('Plant x size'!$B$5:$B$171,A7,'Plant x size'!$P$5:$P$171) -> 0 | J7: =SUMIF('Plant x size'!$B$5:$B$171,A7,'Plant x size'!$Q$5:$Q$171) -> 0 | K7: =SUMIFS('Plant x size'!$P$5:$P$171,'Plant x size'!$B$5:$B$171,A7,'Plant x size'!$A$5:$A$171,"Hyderabad") -> 0 | L7: =SUMIFS('Plant x size'!$P$5:$P$171,'Plant x size'!$B$5:$B$171,A7,'Plant x size'!$A$5:$A$171,"Lepakshi") -> 0 | M7: =SUMIFS('Plant x size'!$P$5:$P$171,'Plant x size'!$B$5:$B$171,A7,'Plant x size'!$A$5:$A$171,"NPMD") -> 0 | N7: =SUMIFS('Plant x size'!$P$5:$P$171,'Plant x size'!$B$5:$B$171,A7,'Plant x size'!$A$5:$A$171,"Tapi") -> 0
A8: SHS 30x30 x 2.5 | B8: =SUMIF('Plant x size'!$B$5:$B$171,A8,'Plant x size'!$C$5:$C$171) -> 3.4545625 | C8: =SUMIF('Plant x size'!$B$5:$B$171,A8,'Plant x size'!$D$5:$D$171) -> 3.03 | D8: =SUMIF('Plant x size'!$B$5:$B$171,A8,'Plant x size'!$K$5:$K$171) -> 0.89749134 | E8: =SUMIF('Plant x size'!$B$5:$B$171,A8,'Plant x size'!$L$5:$L$171) -> 0 | F8: =SUMIF('Plant x size'!$B$5:$B$171,A8,'Plant x size'!$M$5:$M$171) -> 0 | G8: =SUMIF('Plant x size'!$B$5:$B$171,A8,'Plant x size'!$N$5:$N$171) -> 2.1325087 | H8: =SUMIF('Plant x size'!$B$5:$B$171,A8,'Plant x size'!$O$5:$O$171) -> 0 | I8: =SUMIF('Plant x size'!$B$5:$B$171,A8,'Plant x size'!$P$5:$P$171) -> 3.03 | J8: =SUMIF('Plant x size'!$B$5:$B$171,A8,'Plant x size'!$Q$5:$Q$171) -> 2.1325087 | K8: =SUMIFS('Plant x size'!$P$5:$P$171,'Plant x size'!$B$5:$B$171,A8,'Plant x size'!$A$5:$A$171,"Hyderabad") -> 3.03 | L8: =SUMIFS('Plant x size'!$P$5:$P$171,'Plant x size'!$B$5:$B$171,A8,'Plant x size'!$A$5:$A$171,"Lepakshi") -> 0 | M8: =SUMIFS('Plant x size'!$P$5:$P$171,'Plant x size'!$B$5:$B$171,A8,'Plant x size'!$A$5:$A$171,"NPMD") -> 0 | N8: =SUMIFS('Plant x size'!$P$5:$P$171,'Plant x size'!$B$5:$B$171,A8,'Plant x size'!$A$5:$A$171,"Tapi") -> 0
A9: SHS 38x38 x 1.6 | B9: =SUMIF('Plant x size'!$B$5:$B$171,A9,'Plant x size'!$C$5:$C$171) -> 1.1760019 | C9: =SUMIF('Plant x size'!$B$5:$B$171,A9,'Plant x size'!$D$5:$D$171) -> 0 | D9: =SUMIF('Plant x size'!$B$5:$B$171,A9,'Plant x size'!$K$5:$K$171) -> 0 | E9: =SUMIF('Plant x size'!$B$5:$B$171,A9,'Plant x size'!$L$5:$L$171) -> 0 | F9: =SUMIF('Plant x size'!$B$5:$B$171,A9,'Plant x size'!$M$5:$M$171) -> 0 | G9: =SUMIF('Plant x size'!$B$5:$B$171,A9,'Plant x size'!$N$5:$N$171) -> 0 | H9: =SUMIF('Plant x size'!$B$5:$B$171,A9,'Plant x size'!$O$5:$O$171) -> 0 | I9: =SUMIF('Plant x size'!$B$5:$B$171,A9,'Plant x size'!$P$5:$P$171) -> 0 | J9: =SUMIF('Plant x size'!$B$5:$B$171,A9,'Plant x size'!$Q$5:$Q$171) -> 0 | K9: =SUMIFS('Plant x size'!$P$5:$P$171,'Plant x size'!$B$5:$B$171,A9,'Plant x size'!$A$5:$A$171,"Hyderabad") -> 0 | L9: =SUMIFS('Plant x size'!$P$5:$P$171,'Plant x size'!$B$5:$B$171,A9,'Plant x size'!$A$5:$A$171,"Lepakshi") -> 0 | M9: =SUMIFS('Plant x size'!$P$5:$P$171,'Plant x size'!$B$5:$B$171,A9,'Plant x size'!$A$5:$A$171,"NPMD") -> 0 | N9: =SUMIFS('Plant x size'!$P$5:$P$171,'Plant x size'!$B$5:$B$171,A9,'Plant x size'!$A$5:$A$171,"Tapi") -> 0
A10: SHS 38x38 x 2 | B10: =SUMIF('Plant x size'!$B$5:$B$171,A10,'Plant x size'!$C$5:$C$171) -> 31.99696 | C10: =SUMIF('Plant x size'!$B$5:$B$171,A10,'Plant x size'!$D$5:$D$171) -> 34.503 | D10: =SUMIF('Plant x size'!$B$5:$B$171,A10,'Plant x size'!$K$5:$K$171) -> 34.503 | E10: =SUMIF('Plant x size'!$B$5:$B$171,A10,'Plant x size'!$L$5:$L$171) -> 0 | F10: =SUMIF('Plant x size'!$B$5:$B$171,A10,'Plant x size'!$M$5:$M$171) -> 0 | G10: =SUMIF('Plant x size'!$B$5:$B$171,A10,'Plant x size'!$N$5:$N$171) -> 0 | H10: =SUMIF('Plant x size'!$B$5:$B$171,A10,'Plant x size'!$O$5:$O$171) -> 0 | I10: =SUMIF('Plant x size'!$B$5:$B$171,A10,'Plant x size'!$P$5:$P$171) -> 34.503 | J10: =SUMIF('Plant x size'!$B$5:$B$171,A10,'Plant x size'!$Q$5:$Q$171) -> 0 | K10: =SUMIFS('Plant x size'!$P$5:$P$171,'Plant x size'!$B$5:$B$171,A10,'Plant x size'!$A$5:$A$171,"Hyderabad") -> 34.503 | L10: =SUMIFS('Plant x size'!$P$5:$P$171,'Plant x size'!$B$5:$B$171,A10,'Plant x size'!$A$5:$A$171,"Lepakshi") -> 0 | M10: =SUMIFS('Plant x size'!$P$5:$P$171,'Plant x size'!$B$5:$B$171,A10,'Plant x size'!$A$5:$A$171,"NPMD") -> 0 | N10: =SUMIFS('Plant x size'!$P$5:$P$171,'Plant x size'!$B$5:$B$171,A10,'Plant x size'!$A$5:$A$171,"Tapi") -> 0
A11: SHS 38x38 x 2.5 | B11: =SUMIF('Plant x size'!$B$5:$B$171,A11,'Plant x size'!$C$5:$C$171) -> 23.161798 | C11: =SUMIF('Plant x size'!$B$5:$B$171,A11,'Plant x size'!$D$5:$D$171) -> 19.677 | D11: =SUMIF('Plant x size'!$B$5:$B$171,A11,'Plant x size'!$K$5:$K$171) -> 17.102609 | E11: =SUMIF('Plant x size'!$B$5:$B$171,A11,'Plant x size'!$L$5:$L$171) -> 2.5743912 | F11: =SUMIF('Plant x size'!$B$5:$B$171,A11,'Plant x size'!$M$5:$M$171) -> 0 | G11: =SUMIF('Plant x size'!$B$5:$B$171,A11,'Plant x size'!$N$5:$N$171) -> 0 | H11: =SUMIF('Plant x size'!$B$5:$B$171,A11,'Plant x size'!$O$5:$O$171) -> 0 | I11: =SUMIF('Plant x size'!$B$5:$B$171,A11,'Plant x size'!$P$5:$P$171) -> 19.677 | J11: =SUMIF('Plant x size'!$B$5:$B$171,A11,'Plant x size'!$Q$5:$Q$171) -> 0 | K11: =SUMIFS('Plant x size'!$P$5:$P$171,'Plant x size'!$B$5:$B$171,A11,'Plant x size'!$A$5:$A$171,"Hyderabad") -> 19.677 | L11: =SUMIFS('Plant x size'!$P$5:$P$171,'Plant x size'!$B$5:$B$171,A11,'Plant x size'!$A$5:$A$171,"Lepakshi") -> 0 | M11: =SUMIFS('Plant x size'!$P$5:$P$171,'Plant x size'!$B$5:$B$171,A11,'Plant x size'!$A$5:$A$171,"NPMD") -> 0 | N11: =SUMIFS('Plant x size'!$P$5:$P$171,'Plant x size'!$B$5:$B$171,A11,'Plant x size'!$A$5:$A$171,"Tapi") -> 0
A12: SHS 38x38 x 3 | B12: =SUMIF('Plant x size'!$B$5:$B$171,A12,'Plant x size'!$C$5:$C$171) -> 8.1270124 | C12: =SUMIF('Plant x size'!$B$5:$B$171,A12,'Plant x size'!$D$5:$D$171) -> 13.237 | D12: =SUMIF('Plant x size'!$B$5:$B$171,A12,'Plant x size'!$K$5:$K$171) -> 0 | E12: =SUMIF('Plant x size'!$B$5:$B$171,A12,'Plant x size'!$L$5:$L$171) -> 13.237 | F12: =SUMIF('Plant x size'!$B$5:$B$171,A12,'Plant x size'!$M$5:$M$171) -> 0 | G12: =SUMIF('Plant x size'!$B$5:$B$171,A12,'Plant x size'!$N$5:$N$171) -> 0 | H12: =SUMIF('Plant x size'!$B$5:$B$171,A12,'Plant x size'!$O$5:$O$171) -> 0 | I12: =SUMIF('Plant x size'!$B$5:$B$171,A12,'Plant x size'!$P$5:$P$171) -> 13.237 | J12: =SUMIF('Plant x size'!$B$5:$B$171,A12,'Plant x size'!$Q$5:$Q$171) -> 0 | K12: =SUMIFS('Plant x size'!$P$5:$P$171,'Plant x size'!$B$5:$B$171,A12,'Plant x size'!$A$5:$A$171,"Hyderabad") -> 13.237 | L12: =SUMIFS('Plant x size'!$P$5:$P$171,'Plant x size'!$B$5:$B$171,A12,'Plant x size'!$A$5:$A$171,"Lepakshi") -> 0 | M12: =SUMIFS('Plant x size'!$P$5:$P$171,'Plant x size'!$B$5:$B$171,A12,'Plant x size'!$A$5:$A$171,"NPMD") -> 0 | N12: =SUMIFS('Plant x size'!$P$5:$P$171,'Plant x size'!$B$5:$B$171,A12,'Plant x size'!$A$5:$A$171,"Tapi") -> 0
A13: SHS 38x38 x 4 | B13: =SUMIF('Plant x size'!$B$5:$B$171,A13,'Plant x size'!$C$5:$C$171) -> 0.062 | C13: =SUMIF('Plant x size'!$B$5:$B$171,A13,'Plant x size'!$D$5:$D$171) -> 0 | D13: =SUMIF('Plant x size'!$B$5:$B$171,A13,'Plant x size'!$K$5:$K$171) -> 0 | E13: =SUMIF('Plant x size'!$B$5:$B$171,A13,'Plant x size'!$L$5:$L$171) -> 0 | F13: =SUMIF('Plant x size'!$B$5:$B$171,A13,'Plant x size'!$M$5:$M$171) -> 0 | G13: =SUMIF('Plant x size'!$B$5:$B$171,A13,'Plant x size'!$N$5:$N$171) -> 0 | H13: =SUMIF('Plant x size'!$B$5:$B$171,A13,'Plant x size'!$O$5:$O$171) -> 0 | I13: =SUMIF('Plant x size'!$B$5:$B$171,A13,'Plant x size'!$P$5:$P$171) -> 0 | J13: =SUMIF('Plant x size'!$B$5:$B$171,A13,'Plant x size'!$Q$5:$Q$171) -> 0 | K13: =SUMIFS('Plant x size'!$P$5:$P$171,'Plant x size'!$B$5:$B$171,A13,'Plant x size'!$A$5:$A$171,"Hyderabad") -> 0 | L13: =SUMIFS('Plant x size'!$P$5:$P$171,'Plant x size'!$B$5:$B$171,A13,'Plant x size'!$A$5:$A$171,"Lepakshi") -> 0 | M13: =SUMIFS('Plant x size'!$P$5:$P$171,'Plant x size'!$B$5:$B$171,A13,'Plant x size'!$A$5:$A$171,"NPMD") -> 0 | N13: =SUMIFS('Plant x size'!$P$5:$P$171,'Plant x size'!$B$5:$B$171,A13,'Plant x size'!$A$5:$A$171,"Tapi") -> 0
A14: SHS 40x40 x 2 | B14: =SUMIF('Plant x size'!$B$5:$B$171,A14,'Plant x size'!$C$5:$C$171) -> 5.6647888 | C14: =SUMIF('Plant x size'!$B$5:$B$171,A14,'Plant x size'!$D$5:$D$171) -> 2.4 | D14: =SUMIF('Plant x size'!$B$5:$B$171,A14,'Plant x size'!$K$5:$K$171) -> 2.4 | E14: =SUMIF('Plant x size'!$B$5:$B$171,A14,'Plant x size'!$L$5:$L$171) -> 0 | F14: =SUMIF('Plant x size'!$B$5:$B$171,A14,'Plant x size'!$M$5:$M$171) -> 0 | G14: =SUMIF('Plant x size'!$B$5:$B$171,A14,'Plant x size'!$N$5:$N$171) -> 0 | H14: =SUMIF('Plant x size'!$B$5:$B$171,A14,'Plant x size'!$O$5:$O$171) -> 0 | I14: =SUMIF('Plant x size'!$B$5:$B$171,A14,'Plant x size'!$P$5:$P$171) -> 2.4 | J14: =SUMIF('Plant x size'!$B$5:$B$171,A14,'Plant x size'!$Q$5:$Q$171) -> 0 | K14: =SUMIFS('Plant x size'!$P$5:$P$171,'Plant x size'!$B$5:$B$171,A14,'Plant x size'!$A$5:$A$171,"Hyderabad") -> 0 | L14: =SUMIFS('Plant x size'!$P$5:$P$171,'Plant x size'!$B$5:$B$171,A14,'Plant x size'!$A$5:$A$171,"Lepakshi") -> 2.4 | M14: =SUMIFS('Plant x size'!$P$5:$P$171,'Plant x size'!$B$5:$B$171,A14,'Plant x size'!$A$5:$A$171,"NPMD") -> 0 | N14: =SUMIFS('Plant x size'!$P$5:$P$171,'Plant x size'!$B$5:$B$171,A14,'Plant x size'!$A$5:$A$171,"Tapi") -> 0
A15: SHS 40x40 x 2.5 | B15: =SUMIF('Plant x size'!$B$5:$B$171,A15,'Plant x size'!$C$5:$C$171) -> 6.5123125 | C15: =SUMIF('Plant x size'!$B$5:$B$171,A15,'Plant x size'!$D$5:$D$171) -> 0 | D15: =SUMIF('Plant x size'!$B$5:$B$171,A15,'Plant x size'!$K$5:$K$171) -> 0 | E15: =SUMIF('Plant x size'!$B$5:$B$171,A15,'Plant x size'!$L$5:$L$171) -> 0 | F15: =SUMIF('Plant x size'!$B$5:$B$171,A15,'Plant x size'!$M$5:$M$171) -> 0 | G15: =SUMIF('Plant x size'!$B$5:$B$171,A15,'Plant x size'!$N$5:$N$171) -> 0 | H15: =SUMIF('Plant x size'!$B$5:$B$171,A15,'Plant x size'!$O$5:$O$171) -> 0 | I15: =SUMIF('Plant x size'!$B$5:$B$171,A15,'Plant x size'!$P$5:$P$171) -> 0 | J15: =SUMIF('Plant x size'!$B$5:$B$171,A15,'Plant x size'!$Q$5:$Q$171) -> 0 | K15: =SUMIFS('Plant x size'!$P$5:$P$171,'Plant x size'!$B$5:$B$171,A15,'Plant x size'!$A$5:$A$171,"Hyderabad") -> 0 | L15: =SUMIFS('Plant x size'!$P$5:$P$171,'Plant x size'!$B$5:$B$171,A15,'Plant x size'!$A$5:$A$171,"Lepakshi") -> 0 | M15: =SUMIFS('Plant x size'!$P$5:$P$171,'Plant x size'!$B$5:$B$171,A15,'Plant x size'!$A$5:$A$171,"NPMD") -> 0 | N15: =SUMIFS('Plant x size'!$P$5:$P$171,'Plant x size'!$B$5:$B$171,A15,'Plant x size'!$A$5:$A$171,"Tapi") -> 0
... A118: CHS 80 NB x 4 | B118: =SUMIF('Plant x size'!$B$5:$B$171,A118,'Plant x size'!$C$5:$C$171) -> 19.5961 | C118: =SUMIF('Plant x size'!$B$5:$B$171,A118,'Plant x size'!$D$5:$D$171) -> 19.762 | D118: =SUMIF('Plant x size'!$B$5:$B$171,A118,'Plant x size'!$K$5:$K$171) -> 19.762 | E118: =SUMIF('Plant x size'!$B$5:$B$171,A118,'Plant x size'!$L$5:$L$171) -> 0 | F118: =SUMIF('Plant x size'!$B$5:$B$171,A118,'Plant x size'!$M$5:$M$171) -> 0 | G118: =SUMIF('Plant x size'!$B$5:$B$171,A118,'Plant x size'!$N$5:$N$171) -> 0 | H118: =SUMIF('Plant x size'!$B$5:$B$171,A118,'Plant x size'!$O$5:$O$171) -> 0 | I118: =SUMIF('Plant x size'!$B$5:$B$171,A118,'Plant x size'!$P$5:$P$171) -> 19.762 | J118: =SUMIF('Plant x size'!$B$5:$B$171,A118,'Plant x size'!$Q$5:$Q$171) -> 0 | K118: =SUMIFS('Plant x size'!$P$5:$P$171,'Plant x size'!$B$5:$B$171,A118,'Plant x size'!$A$5:$A$171,"Hyderabad") -> 19.762 | L118: =SUMIFS('Plant x size'!$P$5:$P$171,'Plant x size'!$B$5:$B$171,A118,'Plant x size'!$A$5:$A$171,"Lepakshi") -> 0 | M118: =SUMIFS('Plant x size'!$P$5:$P$171,'Plant x size'!$B$5:$B$171,A118,'Plant x size'!$A$5:$A$171,"NPMD") -> 0 | N118: =SUMIFS('Plant x size'!$P$5:$P$171,'Plant x size'!$B$5:$B$171,A118,'Plant x size'!$A$5:$A$171,"Tapi") -> 0
A119: Total (follows the filter) | B119: =SUBTOTAL(9,B4:B118) -> 2573.4966 | C119: =SUBTOTAL(9,C4:C118) -> 2630.732 | D119: =SUBTOTAL(9,D4:D118) -> 1997.1604 | E119: =SUBTOTAL(9,E4:E118) -> 315.05159 | F119: =SUBTOTAL(9,F4:F118) -> 14.464 | G119: =SUBTOTAL(9,G4:G118) -> 205.72501 | H119: =SUBTOTAL(9,H4:H118) -> 98.331 | I119: =SUBTOTAL(9,I4:I118) -> 2630.732 | ... N119: =SUBTOTAL(9,N4:N118) -> 827
